Workbook

Sheet 0.협의안
B2: 안1 | C2: 8개 선정기준 + 역사등급 고려 => 10개역 실내내비
B18: 안2 | C18: 제안서 제안(안1+장애단체 의견) => 10개역 실내내비
B40: 안3 | C40: 안1,2고려 + 연속위치 => 10개역 실내내비
B54: 안4 | C54: 안3(10개역사 실내내비) + 실내지도DB제작 ㄴ 서울시 제공 참조자료 기준 실내지도DB구축, 현장조사 제외, 서비스 미적용 ㄴ 26년, 27년 단계별 실내지도DB구축 및 실내내비게이션 단계별 확대

Sheet 1.지하철등급
A1: 서울시 지하철역 등급
A2: 순번 | B2: 역명 | C2: 등급 | D2: 면적점수 | E2: 환승점수 | F2: 지하상가점수 | G2: 연면적(㎡) | H2: 환승노선 | I2: 환승노선수 | J2: 비고
A3: 1 | B3: 서울 | C3: 특 | D3: 5 | E3: 4 | F3: 3 | G3: 176481 | H3: 1·4·경의중앙·공항철도 | I3: 4 | J3: 복합역사(특); =서울역
A4: 2 | B4: 영등포 | C4: 특 | D4: 5 | E4: 1 | F4: 1 | G4: 156932 | H4: 1 | I4: 1 | J4: 복합역사(특); 지하상가 +18,392㎡
A5: 3 | B5: 왕십리 | C5: 특 | D5: 5 | E5: 4 | F5: 3 | G5: 108571 | H5: 2·5·경의중앙·수인분당 | I5: 4 | J5: 복합역사(특)
A6: 4 | B6: 고속터미널 | C6: 특 | D6: 5 | E6: 3 | F6: 5 | G6: 108439 | H6: 3·7·9 | I6: 3 | J6: 복합역사(특)
A7: 5 | B7: 수서 | C7: 특 | D7: 5 | E7: 2 | F7: 1 | G7: 102273 | H7: 3·수인분당 | I7: 2 | J7: 복합역사(특)
A8: 6 | B8: 김포공항 | C8: 특 | D8: 5 | E8: 5 | F8: 3 | G8: 78082 | H8: 5·9·공항철도·김포골드·서해 | I8: 5 | J8: 복합역사(특)
A9: 7 | B9: 용산 | C9: 특 | D9: 5 | E9: 2 | F9: 1 | G9: 64126 | H9: 1·경의중앙 | I9: 2 | J9: 복합역사(특)
A10: 8 | B10: 신도림 | C10: 특 | D10: 5 | E10: 2 | F10: 1 | G10: 48749 | H10: 1·2 | I10: 2 | J10: 복합역사(특)
A11: 9 | B11: 청량리 | C11: 특 | D11: 5 | E11: 4 | F11: 5 | G11: 47262 | H11: 1·경의중앙·경춘·수인분당 | I11: 4 | J11: 복합역사(특)
A12: 10 | B12: 잠실 | C12: 특 | D12: 3 | G12: 23561 | H12: 2·8 | I12: 2 | J12: 복합역사(특); 면적=8호선 잠실역 23,561㎡(2호선·롯데 일체 미합산)
A13: 11 | B13: 공덕 | C13: A | D13: 5 | E13: 4 | F13: 1 | G13: 63611 | H13: 5·6·경의중앙·공항철도 | I13: 4
A14: 12 | B14: 디지털미디어시티 | C14: A | D14: 5 | E14: 3 | F14: 1 | G14: 56903 | H14: 6·경의중앙·공항철도 | I14: 3
A15: 13 | B15: 신논현 | C15: B | D15: 5 | E15: 2 | F15: 1 | G15: 47489 | H15: 9·신분당 | I15: 2
A16: 14 | B16: 동대문역사문화공원 | C16: A | D16: 5 | E16: 3 | F16: 5 | G16: 47052 | H16: 2·4·5 | I16: 3
A17: 15 | B17: 동작 | C17: B | D17: 5 | E17: 2 | F17: 1 | G17: 42317 | H17: 4·9 | I17: 2
A18: 16 | B18: 강남 | C18: A | D18: 5 | E18: 2 | F18: 5 | G18: 42266 | H18: 2·신분당 | I18: 2
A19: 17 | B19: 종로3가 | C19: A | D19: 5 | E19: 3 | F19: 3 | G19: 41329 | H19: 1·3·5 | I19: 3
A20: 18 | B20: 종합운동장 | C20: B | D20: 5 | E20: 2 | F20: 1 | G20: 40102 | H20: 2·9 | I20: 2
A21: 19 | B21: 영등포구청 | C21: A | D21: 4 | E21: 2 | F21: 5 | G21: 38693 | H21: 2·5 | I21: 2
A22: 20 | B22: 신길 | C22: B | D22: 4 | E22: 2 | F22: 1 | G22: 38643 | H22: 1·5 | I22: 2
A23: 21 | B23: 신당 | C23: B | D23: 4 | E23: 2 | F23: 1 | G23: 38117 | H23: 2·6 | I23: 2 | J23: 지하상가 +4,801㎡
A24: 22 | B24: 홍대입구 | C24: A | D24: 4 | E24: 3 | F24: 3 | G24: 37760 | H24: 2·경의중앙·공항철도 | I24: 3
A25: 23 | B25: 도곡 | C25: B | D25: 4 | E25: 2 | F25: 1 | G25: 37750 | H25: 3·수인분당 | I25: 2
A26: 24 | B26: 가락시장 | C26: B | D26: 4 | E26: 2 | F26: 1 | G26: 37381 | H26: 3·8 | I26: 2
A27: 25 | B27: 양재 | C27: B | D27: 4 | E27: 2 | F27: 1 | G27: 36076 | H27: 3·신분당 | I27: 2
A28: 26 | B28: 동묘앞 | C28: B | D28: 4 | E28: 2 | F28: 1 | G28: 35058 | H28: 1·6 | I28: 2
A29: 27 | B29: 시청 | C29: A | D29: 4 | E29: 2 | F29: 3 | G29: 34895 | H29: 1·2 | I29: 2 | J29: 지하상가 +5,441㎡
A30: 28 | B30: 오금 | C30: B | D30: 4 | E30: 2 | F30: 1 | G30: 33981 | H30: 3·5 | I30: 2
A31: 29 | B31: 태릉입구 | C31: B | D31: 4 | E31: 2 | F31: 1 | G31: 33673 | H31: 6·7 | I31: 2
A32: 30 | B32: 사당 | C32: A | D32: 4 | E32: 2 | F32: 3 | G32: 32955 | H32: 2·4 | I32: 2
A33: 31 | B33: 선정릉 | C33: B | D33: 4 | E33: 2 | F33: 1 | G33: 32825 | H33: 9·수인분당 | I33: 2
A34: 32 | B34: 신사 | C34: A | D34: 4 | E34: 2 | F34: 3 | G34: 32310 | H34: 3·신분당 | I34: 2
A35: 33 | B35: 노량진 | C35: B | D35: 4 | E35: 2 | F35: 1 | G35: 32308 | H35: 1·9 | I35: 2
A36: 34 | B36: 삼각지 | C36: B | D36: 4 | E36: 2 | F36: 1 | G36: 32249 | H36: 4·6 | I36: 2
A37: 35 | B37: 강남구청 | C37: B | D37: 4 | E37: 2 | F37: 1 | G37: 32126 | H37: 7·수인분당 | I37: 2
A38: 36 | B38: 신촌 | C38: A | D38: 4 | E38: 2 | F38: 3 | G38: 31638 | H38: 2·경의중앙 | I38: 2
A39: 37 | B39: 총신대입구(이수) | C39: B | D39: 4 | E39: 2 | F39: 1 | G39: 31335 | H39: 4·7 | I39: 2
A40: 38 | B40: 회현 | C40: A | D40: 4 | E40: 1 | F40: 5 | G40: 31234 | H40: 4 | I40: 1 | J40: 지하상가 +16,405㎡
...

Sheet 3.등급별비용
M2: 인건비 | N2: 400000 | O2: 사업비 | P2: =N2+(N2*120%)+(N2+(N2*120%))*20% -> 1056000
B3: 등급 | C3: 합계(1개역) | E3: 합계(1개역) 세부내역 | Q3: 합계(전체역) | T3: 합계(전체역) 세부내역
E4: 실내지도 | M4: 실내 내비게이션 | T4: 실내지도 | AB4: 실내 내비게이션
E5: 실내지도DB제작 | G5: 현장조사 | I5: 현장조사DB반영 | K5: 실내지도 서비스 (지도검색+지도화면+길찾기) | M5: 실내측위DB및기술 | O5: 실내내비 서비스 (실내지도+현위치+길안내) | T5: 실내지도DB제작 | V5: 현장조사 | X5: 현장조사DB반영 | Z5: 실내지도 서비스 (지도검색+지도화면+길찾기) | AB5: 실내측위DB및기술 | AD5: 실내내비 서비스 (실내지도+현위치+길안내)
C6: 작업일 | D6: 비용 | E6: 작업일 | F6: 비용 | G6: 작업일 | H6: 비용 | I6: 작업일 | J6: 비용 | K6: 작업일 | L6: 비용 | M6: 작업일 | N6: 비용 | O6: 작업일 | P6: 비용 | Q6: 역개수 | R6: 작업일 | S6: 비용 | T6: 작업일 | U6: 비용 | V6: 작업일 | W6: 비용 | X6: 작업일 | Y6: 비용 | Z6: 작업일 | AA6: 비용 | AB6: 작업일 | AC6: 비용 | AD6: 작업일 | AE6: 비용
B7: 특 | C7: =SUM(E7,G7,I7,K7,M7,O7) -> 100.98 | D7: =SUM(F7,H7,J7,L7,N7,P7) -> 106634880 | E7: 18 | F7: =E7*INDEX($P$2,1) -> 19008000 | G7: =E7*50% -> 9 | H7: =G7*INDEX($P$2,1) -> 9504000 | I7: =E7*30% -> 5.4 | J7: =I7*INDEX($P$2,1) -> 5702400 | K7: =E7*70% -> 12.6 | L7: =K7*INDEX($P$2,1) -> 13305600 | M7: =SUM(E7,G7,I7)*130% -> 42.12 | N7: =M7*INDEX($P$2,1) -> 44478720 | O7: =K7*110% -> 13.86 | P7: =O7*INDEX($P$2,1) -> 14636160 | Q7: 10 | R7: =SUM(T7,V7,X7,Z7,AB7,AD7) -> 1009.8 | S7: =SUM(U7,W7,Y7,AA7,AC7,AE7) -> 1066348800 | T7: =E7*$Q7 -> 180 | U7: =Q7*F7 -> 190080000 | V7: =G7*$Q7 -> 90 | W7: =Q7*H7 -> 95040000 | X7: =I7*$Q7 -> 54 | Y7: =Q7*J7 -> 57024000 | Z7: =K7*$Q7 -> 126 | AA7: =Q7*L7 -> 133056000 | AB7: =M7*$Q7 -> 421.2 | AC7: =Q7*N7 -> 444787200 | AD7: =O7*$Q7 -> 138.6 | AE7: =Q7*P7 -> 1.463616e+08
B8: A | C8: =SUM(E8,G8,I8,K8,M8,O8) -> 56.1 | D8: =SUM(F8,H8,J8,L8,N8,P8) -> 59241600 | E8: 10 | F8: =E8*INDEX($P$2,1) -> 10560000 | G8: =E8*50% -> 5 | H8: =G8*INDEX($P$2,1) -> 5280000 | I8: =E8*30% -> 3 | J8: =I8*INDEX($P$2,1) -> 3168000 | K8: =E8*70% -> 7 | L8: =K8*INDEX($P$2,1) -> 7392000 | M8: =SUM(E8,G8,I8)*130% -> 23.4 | N8: =M8*INDEX($P$2,1) -> 24710400 | O8: =K8*110% -> 7.7 | P8: =O8*INDEX($P$2,1) -> 8131200 | Q8: 17 | R8: =SUM(T8,V8,X8,Z8,AB8,AD8) -> 953.7 | S8: =SUM(U8,W8,Y8,AA8,AC8,AE8) -> 1007107200 | T8: =E8*$Q8 -> 170 | U8: =Q8*F8 -> 179520000 | V8: =G8*$Q8 -> 85 | W8: =Q8*H8 -> 89760000 | X8: =I8*$Q8 -> 51 | Y8: =Q8*J8 -> 53856000 | Z8: =K8*$Q8 -> 119 | AA8: =Q8*L8 -> 125664000 | AB8: =M8*$Q8 -> 397.8 | AC8: =Q8*N8 -> 4.200768e+08 | AD8: =O8*$Q8 -> 130.9 | AE8: =Q8*P8 -> 1.382304e+08
B9: B | C9: =SUM(E9,G9,I9,K9,M9,O9) -> 28.05 | D9: =SUM(F9,H9,J9,L9,N9,P9) -> 29620800 | E9: 5 | F9: =E9*INDEX($P$2,1) -> 5280000 | G9: =E9*50% -> 2.5 | H9: =G9*INDEX($P$2,1) -> 2640000 | I9: =E9*30% -> 1.5 | J9: =I9*INDEX($P$2,1) -> 1584000 | K9: =E9*70% -> 3.5 | L9: =K9*INDEX($P$2,1) -> 3696000 | M9: =SUM(E9,G9,I9)*130% -> 11.7 | N9: =M9*INDEX($P$2,1) -> 12355200 | O9: =K9*110% -> 3.85 | P9: =O9*INDEX($P$2,1) -> 4065600 | Q9: 29 | R9: =SUM(T9,V9,X9,Z9,AB9,AD9) -> 813.45 | S9: =SUM(U9,W9,Y9,AA9,AC9,AE9) -> 859003200 | T9: =E9*$Q9 -> 145 | U9: =Q9*F9 -> 153120000 | V9: =G9*$Q9 -> 72.5 | W9: =Q9*H9 -> 76560000 | X9: =I9*$Q9 -> 43.5 | Y9: =Q9*J9 -> 45936000 | Z9: =K9*$Q9 -> 101.5 | AA9: =Q9*L9 -> 107184000 | AB9: =M9*$Q9 -> 339.3 | AC9: =Q9*N9 -> 3.583008e+08 | AD9: =O9*$Q9 -> 111.65 | AE9: =Q9*P9 -> 1.179024e+08
B10: C | C10: =SUM(E10,G10,I10,K10,M10,O10) -> 22.44 | D10: =SUM(F10,H10,J10,L10,N10,P10) -> 23696640 | E10: 4 | F10: =E10*INDEX($P$2,1) -> 4224000 | G10: =E10*50% -> 2 | H10: =G10*INDEX($P$2,1) -> 2112000 | I10: =E10*30% -> 1.2 | J10: =I10*INDEX($P$2,1) -> 1267200 | K10: =E10*70% -> 2.8 | L10: =K10*INDEX($P$2,1) -> 2956800 | M10: =SUM(E10,G10,I10)*130% -> 9.36 | N10: =M10*INDEX($P$2,1) -> 9884160 | O10: =K10*110% -> 3.08 | P10: =O10*INDEX($P$2,1) -> 3252480 | Q10: 45 | R10: =SUM(T10,V10,X10,Z10,AB10,AD10) -> 1009.8 | S10: =SUM(U10,W10,Y10,AA10,AC10,AE10) -> 1066348800 | T10: =E10*$Q10 -> 180 | U10: =Q10*F10 -> 190080000 | V10: =G10*$Q10 -> 90 | W10: =Q10*H10 -> 95040000 | X10: =I10*$Q10 -> 54 | Y10: =Q10*J10 -> 57024000 | Z10: =K10*$Q10 -> 126 | AA10: =Q10*L10 -> 133056000 | AB10: =M10*$Q10 -> 421.2 | AC10: =Q10*N10 -> 4.447872e+08 | AD10: =O10*$Q10 -> 138.6 | AE10: =Q10*P10 -> 146361600
B11: D | C11: =SUM(E11,G11,I11,K11,M11,O11) -> 11.22 | D11: =SUM(F11,H11,J11,L11,N11,P11) -> 11848320 | E11: 2 | F11: =E11*INDEX($P$2,1) -> 2112000 | G11: =E11*50% -> 1 | H11: =G11*INDEX($P$2,1) -> 1056000 | I11: =E11*30% -> 0.6 | J11: =I11*INDEX($P$2,1) -> 633600 | K11: =E11*70% -> 1.4 | L11: =K11*INDEX($P$2,1) -> 1478400 | M11: =SUM(E11,G11,I11)*130% -> 4.68 | N11: =M11*INDEX($P$2,1) -> 4942080 | O11: =K11*110% -> 1.54 | P11: =O11*INDEX($P$2,1) -> 1626240 | Q11: 110 | R11: =SUM(T11,V11,X11,Z11,AB11,AD11) -> 1234.2 | S11: =SUM(U11,W11,Y11,AA11,AC11,AE11) -> 1303315200 | T11: =E11*$Q11 -> 220 | U11: =Q11*F11 -> 232320000 | V11: =G11*$Q11 -> 110 | W11: =Q11*H11 -> 116160000 | X11: =I11*$Q11 -> 66 | Y11: =Q11*J11 -> 69696000 | Z11: =K11*$Q11 -> 154 | AA11: =Q11*L11 -> 162624000 | AB11: =M11*$Q11 -> 514.8 | AC11: =Q11*N11 -> 5.436288e+08 | AD11: =O11*$Q11 -> 169.4 | AE11: =Q11*P11 -> 178886400
B12: E | C12: =SUM(E12,G12,I12,K12,M12,O12) -> 6.732 | D12: =SUM(F12,H12,J12,L12,N12,P12) -> 7108992 | E12: 1.2 | F12: =E12*INDEX($P$2,1) -> 1267200 | G12: =E12*50% -> 0.6 | H12: =G12*INDEX($P$2,1) -> 633600 | I12: =E12*30% -> 0.36 | J12: =I12*INDEX($P$2,1) -> 380160 | K12: =E12*70% -> 0.84 | L12: =K12*INDEX($P$2,1) -> 887040 | M12: =SUM(E12,G12,I12)*130% -> 2.808 | N12: =M12*INDEX($P$2,1) -> 2965248 | O12: =K12*110% -> 0.924 | P12: =O12*INDEX($P$2,1) -> 975744 | Q12: 95 | R12: =SUM(T12,V12,X12,Z12,AB12,AD12) -> 639.54 | S12: =SUM(U12,W12,Y12,AA12,AC12,AE12) -> 675354240 | T12: =E12*$Q12 -> 114 | U12: =Q12*F12 -> 120384000 | V12: =G12*$Q12 -> 57 | W12: =Q12*H12 -> 60192000 | X12: =I12*$Q12 -> 34.2 | Y12: =Q12*J12 -> 36115200 | Z12: =K12*$Q12 -> 79.8 | AA12: =Q12*L12 -> 84268800 | AB12: =M12*$Q12 -> 266.76 | AC12: =Q12*N12 -> 281698560 | AD12: =O12*$Q12 -> 87.78 | AE12: =Q12*P12 -> 92695680
Q13: =SUM(Q7:Q12) -> 306 | R13: =SUM(R7:R12) -> 5660.49 | S13: =SUM(S7:S12) -> 5977477440 | T13: =SUM(T7:T12) -> 1009 | U13: =SUM(U7:U12) -> 1065504000 | V13: =SUM(V7:V12) -> 504.5 | W13: =SUM(W7:W12) -> 532752000 | X13: =SUM(X7:X12) -> 302.7 | ... AE13: =SUM(AE7:AE12) -> 820438080

Sheet 4.제안
B2: 안1. 제안검토 | E2: 합계 | F2: =SUM(F4:F17) -> 432463680 | G2: =SUM(G4:G17) -> 12 | H2: =SUM(H4:H17) -> 0 | I2: =SUM(I4:I17) -> 3 | J2: =SUM(J4:J17) -> 8 | K2: =SUM(K4:K17) -> 1 | L2: =SUM(L4:L17) -> 0 | M2: =SUM(M4:M17) -> 0
B3: 순번 | C3: 역번호 | D3: 등급 | E3: 역명 | F3: 비용 | G3: 역개수 | H3: 특급 | I3: A급 | J3: B급 | K3: C급 | L3: D급 | M3: E급
B4: 1 | C4: 16 | D4: A | E4: 강남역 | F4: ='3.등급별비용'!D8 -> 59241600 | G4: =SUM(H4:M4) -> 1 | I4: 1
B5: 2 | C5: 17 | D5: A | E5: 종로3가역 | F5: ='3.등급별비용'!D8 -> 59241600 | G5: =SUM(H5:M5) -> 1 | I5: 1
B6: 3 | C6: 41 | D6: A | E6: 동대문역 | F6: ='3.등급별비용'!D8 -> 59241600 | G6: =SUM(H6:M6) -> 1 | I6: 1
B7: 4 | C7: 15 | D7: B | E7: 동작역 | F7: ='3.등급별비용'!D9 -> 29620800 | G7: =SUM(H7:M7) -> 1 | J7: 1
B8: 5 | C8: 21 | D8: B | E8: 신당역 | F8: ='3.등급별비용'!D9 -> 29620800 | G8: =SUM(H8:M8) -> 1 | J8: 1
B9: 6 | C9: 37 | D9: B | E9: 총신대입구(이수) | F9: ='3.등급별비용'!D9 -> 29620800 | G9: =SUM(H9:M9) -> 1 | J9: 1
B10: 7 | C10: 53 | D10: B | E10: 선릉역 | F10: ='3.등급별비용'!D9 -> 29620800 | G10: =SUM(H10:M10) -> 1 | J10: 1
B11: 8 | C11: 60 | D11: B | E11: 교대역 | F11: ='3.등급별비용'!D9 -> 29620800 | G11: =SUM(H11:M11) -> 1 | J11: 1
B12: 9 | C12: 66 | D12: B | E12: 충무로역 | F12: ='3.등급별비용'!D9 -> 29620800 | G12: =SUM(H12:M12) -> 1 | J12: 1
B13: 10 | C13: 75 | D13: C | E13: 건대입구역 | F13: ='3.등급별비용'!D10 -> 23696640 | G13: =SUM(H13:M13) -> 1 | K13: 1
B14: 11 | C14: 43 | D14: B | E14: 합정역(예비) | F14: ='3.등급별비용'!D9 -> 29620800 | G14: =SUM(H14:M14) -> 1 | J14: 1
B15: 12 | C15: 85 | D15: B | E15: 신림역(예비) | F15: ='3.등급별비용'!D10 -> 23696640 | G15: =SUM(H15:M15) -> 1 | J15: 1
C16: 46 | D16: C | E16: 온수역(예비) | G16: =SUM(H16:M16) -> 0
C17: 86 | D17: C | E17: 보라매역(예비) | G17: =SUM(H17:M17) -> 0
B19: 안2. 제안서 안 | E19: 합계 | F19: =SUM(F21:F32) -> 687202560 | G19: =SUM(G21:G30) -> 10 | H19: =SUM(H21:H30) -> 4 | I19: =SUM(I21:I30) -> 3 | J19: =SUM(J21:J30) -> 2 | K19: =SUM(K21:K30) -> 1 | L19: =SUM(L21:L30) -> 0 | M19: =SUM(M21:M30) -> 0
B20: 순번 | C20: 역번호 | D20: 등급 | E20: 역명 | F20: 비용 | G20: 역개수 | H20: 특급 | I20: A급 | J20: B급 | K20: C급 | L20: D급 | M20: E급
B21: 1 | C21: 1 | D21: 특 | E21: 서울역 | F21: ='3.등급별비용'!D7 -> 106634880 | G21: =SUM(H21:M21) -> 1 | H21: 1
B22: 2 | C22: 4 | D22: 특 | E22: 고속터미널역 | F22: ='3.등급별비용'!D7 -> 106634880 | G22: =SUM(H22:M22) -> 1 | H22: 1
B23: 3 | C23: 8 | D23: 특 | E23: 신도림역 | F23: ='3.등급별비용'!D7 -> 106634880 | G23: =SUM(H23:M23) -> 1 | H23: 1
B24: 4 | C24: 10 | D24: 특 | E24: 잠실역 | F24: ='3.등급별비용'!D7 -> 106634880 | G24: =SUM(H24:M24) -> 1 | H24: 1
B25: 5 | C25: 16 | D25: A | E25: 강남역 | F25: ='3.등급별비용'!D8 -> 59241600 | G25: =SUM(H25:M25) -> 1 | I25: 1
B26: 6 | C26: 22 | D26: A | E26: 홍대입구역 | F26: ='3.등급별비용'!D8 -> 59241600 | G26: =SUM(H26:M26) -> 1 | I26: 1
B27: 7 | C27: 30 | D27: A | E27: 사당역 | F27: ='3.등급별비용'!D8 -> 59241600 | G27: =SUM(H27:M27) -> 1 | I27: 1
B28: 8 | C28: 43 | D28: B | E28: 합정역 | F28: ='3.등급별비용'!D9 -> 29620800 | G28: =SUM(H28:M28) -> 1 | J28: 1
B29: 9 | C29: 60 | D29: B | E29: 교대역 | F29: ='3.등급별비용'!D9 -> 29620800 | G29: =SUM(H29:M29) -> 1 | J29: 1
B30: 10 | C30: 75 | D30: C | E30: 건대입구역 | F30: ='3.등급별비용'!D10 -> 23696640 | G30: =SUM(H30:M30) -> 1 | K30: 1
B31: 11 | D31: D | L31: 1
B32: 12 | D32: E | M32: 1
B34: 안3. +실내내비 | E34: 합계 | F34: =SUM(F36:F47) -> 421800192 | G34: =SUM(G36:G45) -> 10 | H34: =SUM(H36:H47) -> 1 | I34: =SUM(I36:I47) -> 2 | J34: =SUM(J36:J47) -> 5 | K34: =SUM(K36:K47) -> 1 | L34: =SUM(L36:L47) -> 2 | M34: =SUM(M36:M47) -> 1
B35: 순번 | C35: 역번호 | D35: 등급 | E35: 역명 | F35: 비용 | G35: 역개수 | H35: 특급 | I35: A급 | J35: B급 | K35: C급 | L35: D급 | M35: E급
B36: 1 | C36: 10 | D36: 특 | E36: 잠실 | F36: ='3.등급별비용'!D7 -> 106634880 | G36: =SUM(H36:M36) -> 1 | H36: 1
B37: 2 | C37: 16 | D37: A | E37: 강남 | F37: ='3.등급별비용'!D8 -> 59241600 | G37: =SUM(H37:M37) -> 1 | I37: 1
B38: 3 | C38: 18 | D38: B | E38: 종합운동장 | F38: ='3.등급별비용'!D9 -> 29620800 | G38: =SUM(H38:M38) -> 1 | J38: 1
B39: 4 | C39: 30 | D39: A | E39: 사당 | F39: ='3.등급별비용'!D8 -> 59241600 | G39: =SUM(H39:M39) -> 1 | I39: 1
B40: 5 | C40: 45 | D40: C | E40: 남부터미널 | F40: ='3.등급별비용'!D10 -> 23696640 | G40: =SUM(H40:M40) -> 1 | K40: 1
B41: 6 | C41: 53 | D41: B | E41: 선릉 | F41: ='3.등급별비용'!D9 -> 29620800 | G41: =SUM(H41:M41) -> 1 | J41: 1
B42: 7 | C42: 58 | D42: C | E42: 석촌 | F42: ='3.등급별비용'!D10 -> 23696640 | G42: =SUM(H42:M42) -> 1 | J42: 1
B43: 8 | C43: 60 | D43: B | E43: 교대 | F43: ='3.등급별비용'!D9 -> 29620800 | G43: =SUM(H43:M43) -> 1 | J43: 1
...

Sheet 4.제안_단계별비용
M2: 인건비 | N2: 400000 | O2: 사업비 | P2: =N2+(N2*120%)+(N2+(N2*120%))*20% -> 1056000 | Q2: 단계1. 실내지도DB제작
B3: 등급 | C3: 합계(1개역) | E3: 합계(1개역) 세부내역 | Q3: 합계(전체역) | T3: 합계(전체역) 세부내역
E4: 실내지도 | M4: 실내 내비게이션 | T4: 실내지도 | AB4: 실내 내비게이션
E5: 실내지도DB제작 | G5: 현장조사 | I5: 현장조사DB반영 | K5: 실내지도 서비스 (지도검색+지도화면+길찾기) | M5: 실내측위DB및기술 | O5: 실내내비 서비스 (실내지도+현위치+길안내) | T5: 실내지도DB제작 | V5: 현장조사 | X5: 현장조사DB반영 | Z5: 실내지도 서비스 (지도검색+지도화면+길찾기) | AB5: 실내측위DB및기술 | AD5: 실내내비 서비스 (실내지도+현위치+길안내)
C6: 작업일 | D6: 비용 | E6: 작업일 | F6: 비용 | G6: 작업일 | H6: 비용 | I6: 작업일 | J6: 비용 | K6: 작업일 | L6: 비용 | M6: 작업일 | N6: 비용 | O6: 작업일 | P6: 비용 | Q6: 역개수 | R6: 작업일 | S6: 비용 | T6: 작업일 | U6: 비용 | V6: 작업일 | W6: 비용 | X6: 작업일 | Y6: 비용 | Z6: 작업일 | AA6: 비용 | AB6: 작업일 | AC6: 비용 | AD6: 작업일 | AE6: 비용
B7: 특 | C7: =SUM(E7,G7,I7,K7,M7,O7) -> 100.98 | D7: =SUM(F7,H7,J7,L7,N7,P7) -> 106634880 | E7: 18 | F7: =E7*INDEX($P$2,1) -> 19008000 | G7: =E7*50% -> 9 | H7: =G7*INDEX($P$2,1) -> 9504000 | I7: =E7*30% -> 5.4 | J7: =I7*INDEX($P$2,1) -> 5702400 | K7: =E7*70% -> 12.6 | L7: =K7*INDEX($P$2,1) -> 13305600 | M7: =SUM(E7,G7,I7)*130% -> 42.12 | N7: =M7*INDEX($P$2,1) -> 44478720 | O7: =K7*110% -> 13.86 | P7: =O7*INDEX($P$2,1) -> 14636160 | Q7: 10 | R7: =SUM(T7,V7,X7,Z7,AB7,AD7) -> 180 | S7: =SUM(U7,W7,Y7,AA7,AC7,AE7) -> 190080000 | T7: =E7*$Q7 -> 180 | U7: =Q7*F7 -> 190080000
B8: A | C8: =SUM(E8,G8,I8,K8,M8,O8) -> 56.1 | D8: =SUM(F8,H8,J8,L8,N8,P8) -> 59241600 | E8: 10 | F8: =E8*INDEX($P$2,1) -> 10560000 | G8: =E8*50% -> 5 | H8: =G8*INDEX($P$2,1) -> 5280000 | I8: =E8*30% -> 3 | J8: =I8*INDEX($P$2,1) -> 3168000 | K8: =E8*70% -> 7 | L8: =K8*INDEX($P$2,1) -> 7392000 | M8: =SUM(E8,G8,I8)*130% -> 23.4 | N8: =M8*INDEX($P$2,1) -> 24710400 | O8: =K8*110% -> 7.7 | P8: =O8*INDEX($P$2,1) -> 8131200 | Q8: 17 | R8: =SUM(T8,V8,X8,Z8,AB8,AD8) -> 170 | S8: =SUM(U8,W8,Y8,AA8,AC8,AE8) -> 179520000 | T8: =E8*$Q8 -> 170 | U8: =Q8*F8 -> 179520000
B9: B | C9: =SUM(E9,G9,I9,K9,M9,O9) -> 28.05 | D9: =SUM(F9,H9,J9,L9,N9,P9) -> 29620800 | E9: 5 | F9: =E9*INDEX($P$2,1) -> 5280000 | G9: =E9*50% -> 2.5 | H9: =G9*INDEX($P$2,1) -> 2640000 | I9: =E9*30% -> 1.5 | J9: =I9*INDEX($P$2,1) -> 1584000 | K9: =E9*70% -> 3.5 | L9: =K9*INDEX($P$2,1) -> 3696000 | M9: =SUM(E9,G9,I9)*130% -> 11.7 | N9: =M9*INDEX($P$2,1) -> 12355200 | O9: =K9*110% -> 3.85 | P9: =O9*INDEX($P$2,1) -> 4065600 | Q9: 29 | R9: =SUM(T9,V9,X9,Z9,AB9,AD9) -> 145 | S9: =SUM(U9,W9,Y9,AA9,AC9,AE9) -> 153120000 | T9: =E9*$Q9 -> 145 | U9: =Q9*F9 -> 153120000
B10: C | C10: =SUM(E10,G10,I10,K10,M10,O10) -> 22.44 | D10: =SUM(F10,H10,J10,L10,N10,P10) -> 23696640 | E10: 4 | F10: =E10*INDEX($P$2,1) -> 4224000 | G10: =E10*50% -> 2 | H10: =G10*INDEX($P$2,1) -> 2112000 | I10: =E10*30% -> 1.2 | J10: =I10*INDEX($P$2,1) -> 1267200 | K10: =E10*70% -> 2.8 | L10: =K10*INDEX($P$2,1) -> 2956800 | M10: =SUM(E10,G10,I10)*130% -> 9.36 | N10: =M10*INDEX($P$2,1) -> 9884160 | O10: =K10*110% -> 3.08 | P10: =O10*INDEX($P$2,1) -> 3252480 | Q10: 45 | R10: =SUM(T10,V10,X10,Z10,AB10,AD10) -> 180 | S10: =SUM(U10,W10,Y10,AA10,AC10,AE10) -> 190080000 | T10: =E10*$Q10 -> 180 | U10: =Q10*F10 -> 190080000
B11: D | C11: =SUM(E11,G11,I11,K11,M11,O11) -> 11.22 | D11: =SUM(F11,H11,J11,L11,N11,P11) -> 11848320 | E11: 2 | F11: =E11*INDEX($P$2,1) -> 2112000 | G11: =E11*50% -> 1 | H11: =G11*INDEX($P$2,1) -> 1056000 | I11: =E11*30% -> 0.6 | J11: =I11*INDEX($P$2,1) -> 633600 | K11: =E11*70% -> 1.4 | L11: =K11*INDEX($P$2,1) -> 1478400 | M11: =SUM(E11,G11,I11)*130% -> 4.68 | N11: =M11*INDEX($P$2,1) -> 4942080 | O11: =K11*110% -> 1.54 | P11: =O11*INDEX($P$2,1) -> 1626240 | Q11: 110 | R11: =SUM(T11,V11,X11,Z11,AB11,AD11) -> 220 | S11: =SUM(U11,W11,Y11,AA11,AC11,AE11) -> 232320000 | T11: =E11*$Q11 -> 220 | U11: =Q11*F11 -> 232320000
B12: E | C12: =SUM(E12,G12,I12,K12,M12,O12) -> 6.732 | D12: =SUM(F12,H12,J12,L12,N12,P12) -> 7108992 | E12: 1.2 | F12: =E12*INDEX($P$2,1) -> 1267200 | G12: =E12*50% -> 0.6 | H12: =G12*INDEX($P$2,1) -> 633600 | I12: =E12*30% -> 0.36 | J12: =I12*INDEX($P$2,1) -> 380160 | K12: =E12*70% -> 0.84 | L12: =K12*INDEX($P$2,1) -> 887040 | M12: =SUM(E12,G12,I12)*130% -> 2.808 | N12: =M12*INDEX($P$2,1) -> 2965248 | O12: =K12*110% -> 0.924 | P12: =O12*INDEX($P$2,1) -> 975744 | Q12: 95 | R12: =SUM(T12,V12,X12,Z12,AB12,AD12) -> 114 | S12: =SUM(U12,W12,Y12,AA12,AC12,AE12) -> 120384000 | T12: =E12*$Q12 -> 114 | U12: =Q12*F12 -> 120384000
Q13: =SUM(Q7:Q12) -> 306 | R13: =SUM(R7:R12) -> 1009 | S13: =SUM(S7:S12) -> 1065504000 | T13: =SUM(T7:T12) -> 1009 | U13: =SUM(U7:U12) -> 1065504000 | V13: =SUM(V7:V12) -> 0 | W13: =SUM(W7:W12) -> 0 | X13: =SUM(X7:X12) -> 0 | ... AE13: =SUM(AE7:AE12) -> 0
Q15: 단계2. 단계1 + 현장조사-서비스적용
B16: 등급 | C16: 합계(1개역) | E16: 합계(1개역) 세부내역 | Q16: 합계(전체역) | T16: 합계(전체역) 세부내역
E17: 실내지도 | M17: 실내 내비게이션 | T17: 실내지도 | AB17: 실내 내비게이션
E18: 실내지도DB제작 | G18: 현장조사 | I18: 현장조사DB반영 | K18: 실내지도 서비스 (지도검색+지도화면+길찾기) | M18: 실내측위DB및기술 | O18: 실내내비 서비스 (실내지도+현위치+길안내) | T18: 실내지도DB제작 | V18: 현장조사 | X18: 현장조사DB반영 | Z18: 실내지도 서비스 (지도검색+지도화면+길찾기) | AB18: 실내측위DB및기술 | AD18: 실내내비 서비스 (실내지도+현위치+길안내)
C19: 작업일 | D19: 비용 | E19: 작업일 | F19: 비용 | G19: 작업일 | H19: 비용 | I19: 작업일 | J19: 비용 | K19: 작업일 | L19: 비용 | M19: 작업일 | N19: 비용 | O19: 작업일 | P19: 비용 | Q19: 역개수 | R19: 작업일 | S19: 비용 | T19: 작업일 | U19: 비용 | V19: 작업일 | W19: 비용 | X19: 작업일 | Y19: 비용 | Z19: 작업일 | AA19: 비용 | AB19: 작업일 | AC19: 비용 | AD19: 작업일 | AE19: 비용
B20: 특 | C20: =SUM(E20,G20,I20,K20,M20,O20) -> 100.98 | D20: =SUM(F20,H20,J20,L20,N20,P20) -> 106634880 | E20: 18 | F20: =E20*INDEX($P$2,1) -> 19008000 | G20: =E20*50% -> 9 | H20: =G20*INDEX($P$2,1) -> 9504000 | I20: =E20*30% -> 5.4 | J20: =I20*INDEX($P$2,1) -> 5702400 | K20: =E20*70% -> 12.6 | L20: =K20*INDEX($P$2,1) -> 13305600 | M20: =SUM(E20,G20,I20)*130% -> 42.12 | N20: =M20*INDEX($P$2,1) -> 44478720 | O20: =K20*110% -> 13.86 | P20: =O20*INDEX($P$2,1) -> 14636160 | Q20: 10 | R20: =SUM(T20,V20,X20,Z20,AB20,AD20) -> 450 | S20: =SUM(U20,W20,Y20,AA20,AC20,AE20) -> 475200000 | T20: =E20*$Q20 -> 180 | U20: =Q20*F20 -> 190080000 | V20: =G20*$Q20 -> 90 | W20: =Q20*H20 -> 95040000 | X20: =I20*$Q20 -> 54 | Y20: =Q20*J20 -> 57024000 | Z20: =K20*$Q20 -> 126 | AA20: =Q20*L20 -> 133056000
B21: A | C21: =SUM(E21,G21,I21,K21,M21,O21) -> 56.1 | D21: =SUM(F21,H21,J21,L21,N21,P21) -> 59241600 | E21: 10 | F21: =E21*INDEX($P$2,1) -> 10560000 | G21: =E21*50% -> 5 | H21: =G21*INDEX($P$2,1) -> 5280000 | I21: =E21*30% -> 3 | J21: =I21*INDEX($P$2,1) -> 3168000 | K21: =E21*70% -> 7 | L21: =K21*INDEX($P$2,1) -> 7392000 | M21: =SUM(E21,G21,I21)*130% -> 23.4 | N21: =M21*INDEX($P$2,1) -> 24710400 | O21: =K21*110% -> 7.7 | P21: =O21*INDEX($P$2,1) -> 8131200 | Q21: 17 | R21: =SUM(T21,V21,X21,Z21,AB21,AD21) -> 425 | S21: =SUM(U21,W21,Y21,AA21,AC21,AE21) -> 448800000 | T21: =E21*$Q21 -> 170 | U21: =Q21*F21 -> 179520000 | V21: =G21*$Q21 -> 85 | W21: =Q21*H21 -> 89760000 | X21: =I21*$Q21 -> 51 | Y21: =Q21*J21 -> 53856000 | Z21: =K21*$Q21 -> 119 | AA21: =Q21*L21 -> 125664000
B22: B | C22: =SUM(E22,G22,I22,K22,M22,O22) -> 28.05 | D22: =SUM(F22,H22,J22,L22,N22,P22) -> 29620800 | E22: 5 | F22: =E22*INDEX($P$2,1) -> 5280000 | G22: =E22*50% -> 2.5 | H22: =G22*INDEX($P$2,1) -> 2640000 | I22: =E22*30% -> 1.5 | J22: =I22*INDEX($P$2,1) -> 1584000 | K22: =E22*70% -> 3.5 | L22: =K22*INDEX($P$2,1) -> 3696000 | M22: =SUM(E22,G22,I22)*130% -> 11.7 | N22: =M22*INDEX($P$2,1) -> 12355200 | O22: =K22*110% -> 3.85 | P22: =O22*INDEX($P$2,1) -> 4065600 | Q22: 29 | R22: =SUM(T22,V22,X22,Z22,AB22,AD22) -> 362.5 | S22: =SUM(U22,W22,Y22,AA22,AC22,AE22) -> 382800000 | T22: =E22*$Q22 -> 145 | U22: =Q22*F22 -> 153120000 | V22: =G22*$Q22 -> 72.5 | W22: =Q22*H22 -> 76560000 | X22: =I22*$Q22 -> 43.5 | Y22: =Q22*J22 -> 45936000 | Z22: =K22*$Q22 -> 101.5 | AA22: =Q22*L22 -> 107184000
B23: C | C23: =SUM(E23,G23,I23,K23,M23,O23) -> 22.44 | D23: =SUM(F23,H23,J23,L23,N23,P23) -> 23696640 | E23: 4 | F23: =E23*INDEX($P$2,1) -> 4224000 | G23: =E23*50% -> 2 | H23: =G23*INDEX($P$2,1) -> 2112000 | I23: =E23*30% -> 1.2 | J23: =I23*INDEX($P$2,1) -> 1267200 | K23: =E23*70% -> 2.8 | L23: =K23*INDEX($P$2,1) -> 2956800 | M23: =SUM(E23,G23,I23)*130% -> 9.36 | N23: =M23*INDEX($P$2,1) -> 9884160 | O23: =K23*110% -> 3.08 | P23: =O23*INDEX($P$2,1) -> 3252480 | Q23: 45 | R23: =SUM(T23,V23,X23,Z23,AB23,AD23) -> 450 | S23: =SUM(U23,W23,Y23,AA23,AC23,AE23) -> 475200000 | T23: =E23*$Q23 -> 180 | U23: =Q23*F23 -> 190080000 | V23: =G23*$Q23 -> 90 | W23: =Q23*H23 -> 95040000 | X23: =I23*$Q23 -> 54 | Y23: =Q23*J23 -> 57024000 | Z23: =K23*$Q23 -> 126 | AA23: =Q23*L23 -> 133056000
B24: D | C24: =SUM(E24,G24,I24,K24,M24,O24) -> 11.22 | D24: =SUM(F24,H24,J24,L24,N24,P24) -> 11848320 | E24: 2 | F24: =E24*INDEX($P$2,1) -> 2112000 | G24: =E24*50% -> 1 | H24: =G24*INDEX($P$2,1) -> 1056000 | I24: =E24*30% -> 0.6 | J24: =I24*INDEX($P$2,1) -> 633600 | K24: =E24*70% -> 1.4 | L24: =K24*INDEX($P$2,1) -> 1478400 | M24: =SUM(E24,G24,I24)*130% -> 4.68 | N24: =M24*INDEX($P$2,1) -> 4942080 | O24: =K24*110% -> 1.54 | P24: =O24*INDEX($P$2,1) -> 1626240 | Q24: 110 | R24: =SUM(T24,V24,X24,Z24,AB24,AD24) -> 550 | S24: =SUM(U24,W24,Y24,AA24,AC24,AE24) -> 580800000 | T24: =E24*$Q24 -> 220 | U24: =Q24*F24 -> 232320000 | V24: =G24*$Q24 -> 110 | W24: =Q24*H24 -> 116160000 | X24: =I24*$Q24 -> 66 | Y24: =Q24*J24 -> 69696000 | Z24: =K24*$Q24 -> 154 | AA24: =Q24*L24 -> 162624000
B25: E | C25: =SUM(E25,G25,I25,K25,M25,O25) -> 6.732 | D25: =SUM(F25,H25,J25,L25,N25,P25) -> 7108992 | E25: 1.2 | F25: =E25*INDEX($P$2,1) -> 1267200 | G25: =E25*50% -> 0.6 | H25: =G25*INDEX($P$2,1) -> 633600 | I25: =E25*30% -> 0.36 | J25: =I25*INDEX($P$2,1) -> 380160 | K25: =E25*70% -> 0.84 | L25: =K25*INDEX($P$2,1) -> 887040 | M25: =SUM(E25,G25,I25)*130% -> 2.808 | N25: =M25*INDEX($P$2,1) -> 2965248 | O25: =K25*110% -> 0.924 | P25: =O25*INDEX($P$2,1) -> 975744 | Q25: 95 | R25: =SUM(T25,V25,X25,Z25,AB25,AD25) -> 285 | S25: =SUM(U25,W25,Y25,AA25,AC25,AE25) -> 300960000 | T25: =E25*$Q25 -> 114 | U25: =Q25*F25 -> 120384000 | V25: =G25*$Q25 -> 57 | W25: =Q25*H25 -> 60192000 | X25: =I25*$Q25 -> 34.2 | Y25: =Q25*J25 -> 36115200 | Z25: =K25*$Q25 -> 79.8 | AA25: =Q25*L25 -> 84268800
Q26: =SUM(Q20:Q25) -> 306 | R26: =SUM(R20:R25) -> 2522.5 | S26: =SUM(S20:S25) -> 2663760000 | T26: =SUM(T20:T25) -> 1009 | U26: =SUM(U20:U25) -> 1065504000 | V26: =SUM(V20:V25) -> 504.5 | W26: =SUM(W20:W25) -> 532752000 | X26: =SUM(X20:X25) -> 302.7 | ... AE26: =SUM(AE20:AE25) -> 0
Q28: 단계3. 단계2 + 실내내비게이션
B29: 등급 | C29: 합계(1개역) | E29: 합계(1개역) 세부내역 | Q29: 합계(전체역) | T29: 합계(전체역) 세부내역
E30: 실내지도 | M30: 실내 내비게이션 | T30: 실내지도 | AB30: 실내 내비게이션
E31: 실내지도DB제작 | G31: 현장조사 | I31: 현장조사DB반영 | K31: 실내지도 서비스 (지도검색+지도화면+길찾기) | M31: 실내측위DB및기술 | O31: 실내내비 서비스 (실내지도+현위치+길안내) | T31: 실내지도DB제작 | V31: 현장조사 | X31: 현장조사DB반영 | Z31: 실내지도 서비스 (지도검색+지도화면+길찾기) | AB31: 실내측위DB및기술 | AD31: 실내내비 서비스 (실내지도+현위치+길안내)
C32: 작업일 | D32: 비용 | E32: 작업일 | F32: 비용 | G32: 작업일 | H32: 비용 | I32: 작업일 | J32: 비용 | K32: 작업일 | L32: 비용 | M32: 작업일 | N32: 비용 | O32: 작업일 | P32: 비용 | Q32: 역개수 | R32: 작업일 | S32: 비용 | T32: 작업일 | U32: 비용 | V32: 작업일 | W32: 비용 | X32: 작업일 | Y32: 비용 | Z32: 작업일 | AA32: 비용 | AB32: 작업일 | AC32: 비용 | AD32: 작업일 | AE32: 비용
B33: 특 | C33: =SUM(E33,G33,I33,K33,M33,O33) -> 100.98 | D33: =SUM(F33,H33,J33,L33,N33,P33) -> 106634880 | E33: 18 | F33: =E33*INDEX($P$2,1) -> 19008000 | G33: =E33*50% -> 9 | H33: =G33*INDEX($P$2,1) -> 9504000 | I33: =E33*30% -> 5.4 | J33: =I33*INDEX($P$2,1) -> 5702400 | K33: =E33*70% -> 12.6 | L33: =K33*INDEX($P$2,1) -> 13305600 | M33: =SUM(E33,G33,I33)*130% -> 42.12 | N33: =M33*INDEX($P$2,1) -> 44478720 | O33: =K33*110% -> 13.86 | P33: =O33*INDEX($P$2,1) -> 14636160 | Q33: 10 | R33: =SUM(T33,V33,X33,Z33,AB33,AD33) -> 1009.8 | S33: =SUM(U33,W33,Y33,AA33,AC33,AE33) -> 1066348800 | T33: =E33*$Q33 -> 180 | U33: =Q33*F33 -> 190080000 | V33: =G33*$Q33 -> 90 | W33: =Q33*H33 -> 95040000 | X33: =I33*$Q33 -> 54 | Y33: =Q33*J33 -> 57024000 | Z33: =K33*$Q33 -> 126 | AA33: =Q33*L33 -> 133056000 | AB33: =M33*$Q33 -> 421.2 | AC33: =Q33*N33 -> 444787200 | AD33: =O33*$Q33 -> 138.6 | AE33: =Q33*P33 -> 1.463616e+08
B34: A | C34: =SUM(E34,G34,I34,K34,M34,O34) -> 56.1 | D34: =SUM(F34,H34,J34,L34,N34,P34) -> 59241600 | E34: 10 | F34: =E34*INDEX($P$2,1) -> 10560000 | G34: =E34*50% -> 5 | H34: =G34*INDEX($P$2,1) -> 5280000 | I34: =E34*30% -> 3 | J34: =I34*INDEX($P$2,1) -> 3168000 | K34: =E34*70% -> 7 | L34: =K34*INDEX($P$2,1) -> 7392000 | M34: =SUM(E34,G34,I34)*130% -> 23.4 | N34: =M34*INDEX($P$2,1) -> 24710400 | O34: =K34*110% -> 7.7 | P34: =O34*INDEX($P$2,1) -> 8131200 | Q34: 17 | R34: =SUM(T34,V34,X34,Z34,AB34,AD34) -> 953.7 | S34: =SUM(U34,W34,Y34,AA34,AC34,AE34) -> 1007107200 | T34: =E34*$Q34 -> 170 | U34: =Q34*F34 -> 179520000 | V34: =G34*$Q34 -> 85 | W34: =Q34*H34 -> 89760000 | X34: =I34*$Q34 -> 51 | Y34: =Q34*J34 -> 53856000 | Z34: =K34*$Q34 -> 119 | AA34: =Q34*L34 -> 125664000 | AB34: =M34*$Q34 -> 397.8 | AC34: =Q34*N34 -> 4.200768e+08 | AD34: =O34*$Q34 -> 130.9 | AE34: =Q34*P34 -> 1.382304e+08
B35: B | C35: =SUM(E35,G35,I35,K35,M35,O35) -> 28.05 | D35: =SUM(F35,H35,J35,L35,N35,P35) -> 29620800 | E35: 5 | F35: =E35*INDEX($P$2,1) -> 5280000 | G35: =E35*50% -> 2.5 | H35: =G35*INDEX($P$2,1) -> 2640000 | I35: =E35*30% -> 1.5 | J35: =I35*INDEX($P$2,1) -> 1584000 | K35: =E35*70% -> 3.5 | L35: =K35*INDEX($P$2,1) -> 3696000 | M35: =SUM(E35,G35,I35)*130% -> 11.7 | N35: =M35*INDEX($P$2,1) -> 12355200 | O35: =K35*110% -> 3.85 | P35: =O35*INDEX($P$2,1) -> 4065600 | Q35: 29 | R35: =SUM(T35,V35,X35,Z35,AB35,AD35) -> 813.45 | S35: =SUM(U35,W35,Y35,AA35,AC35,AE35) -> 859003200 | T35: =E35*$Q35 -> 145 | U35: =Q35*F35 -> 153120000 | V35: =G35*$Q35 -> 72.5 | W35: =Q35*H35 -> 76560000 | X35: =I35*$Q35 -> 43.5 | Y35: =Q35*J35 -> 45936000 | Z35: =K35*$Q35 -> 101.5 | AA35: =Q35*L35 -> 107184000 | AB35: =M35*$Q35 -> 339.3 | AC35: =Q35*N35 -> 3.583008e+08 | AD35: =O35*$Q35 -> 111.65 | AE35: =Q35*P35 -> 1.179024e+08
B36: C | C36: =SUM(E36,G36,I36,K36,M36,O36) -> 22.44 | D36: =SUM(F36,H36,J36,L36,N36,P36) -> 23696640 | E36: 4 | F36: =E36*INDEX($P$2,1) -> 4224000 | G36: =E36*50% -> 2 | H36: =G36*INDEX($P$2,1) -> 2112000 | I36: =E36*30% -> 1.2 | J36: =I36*INDEX($P$2,1) -> 1267200 | K36: =E36*70% -> 2.8 | L36: =K36*INDEX($P$2,1) -> 2956800 | M36: =SUM(E36,G36,I36)*130% -> 9.36 | N36: =M36*INDEX($P$2,1) -> 9884160 | O36: =K36*110% -> 3.08 | P36: =O36*INDEX($P$2,1) -> 3252480 | Q36: 45 | R36: =SUM(T36,V36,X36,Z36,AB36,AD36) -> 1009.8 | S36: =SUM(U36,W36,Y36,AA36,AC36,AE36) -> 1066348800 | T36: =E36*$Q36 -> 180 | U36: =Q36*F36 -> 190080000 | V36: =G36*$Q36 -> 90 | W36: =Q36*H36 -> 95040000 | X36: =I36*$Q36 -> 54 | Y36: =Q36*J36 -> 57024000 | Z36: =K36*$Q36 -> 126 | AA36: =Q36*L36 -> 133056000 | AB36: =M36*$Q36 -> 421.2 | AC36: =Q36*N36 -> 4.447872e+08 | AD36: =O36*$Q36 -> 138.6 | AE36: =Q36*P36 -> 146361600
B37: D | C37: =SUM(E37,G37,I37,K37,M37,O37) -> 11.22 | D37: =SUM(F37,H37,J37,L37,N37,P37) -> 11848320 | E37: 2 | F37: =E37*INDEX($P$2,1) -> 2112000 | G37: =E37*50% -> 1 | H37: =G37*INDEX($P$2,1) -> 1056000 | I37: =E37*30% -> 0.6 | J37: =I37*INDEX($P$2,1) -> 633600 | K37: =E37*70% -> 1.4 | L37: =K37*INDEX($P$2,1) -> 1478400 | M37: =SUM(E37,G37,I37)*130% -> 4.68 | N37: =M37*INDEX($P$2,1) -> 4942080 | O37: =K37*110% -> 1.54 | P37: =O37*INDEX($P$2,1) -> 1626240 | Q37: 110 | R37: =SUM(T37,V37,X37,Z37,AB37,AD37) -> 1234.2 | S37: =SUM(U37,W37,Y37,AA37,AC37,AE37) -> 1303315200 | T37: =E37*$Q37 -> 220 | U37: =Q37*F37 -> 232320000 | V37: =G37*$Q37 -> 110 | W37: =Q37*H37 -> 116160000 | X37: =I37*$Q37 -> 66 | Y37: =Q37*J37 -> 69696000 | Z37: =K37*$Q37 -> 154 | AA37: =Q37*L37 -> 162624000 | AB37: =M37*$Q37 -> 514.8 | AC37: =Q37*N37 -> 5.436288e+08 | AD37: =O37*$Q37 -> 169.4 | AE37: =Q37*P37 -> 178886400
B38: E | C38: =SUM(E38,G38,I38,K38,M38,O38) -> 6.732 | D38: =SUM(F38,H38,J38,L38,N38,P38) -> 7108992 | E38: 1.2 | F38: =E38*INDEX($P$2,1) -> 1267200 | G38: =E38*50% -> 0.6 | H38: =G38*INDEX($P$2,1) -> 633600 | I38: =E38*30% -> 0.36 | J38: =I38*INDEX($P$2,1) -> 380160 | K38: =E38*70% -> 0.84 | L38: =K38*INDEX($P$2,1) -> 887040 | M38: =SUM(E38,G38,I38)*130% -> 2.808 | N38: =M38*INDEX($P$2,1) -> 2965248 | O38: =K38*110% -> 0.924 | P38: =O38*INDEX($P$2,1) -> 975744 | Q38: 95 | R38: =SUM(T38,V38,X38,Z38,AB38,AD38) -> 639.54 | S38: =SUM(U38,W38,Y38,AA38,AC38,AE38) -> 675354240 | T38: =E38*$Q38 -> 114 | U38: =Q38*F38 -> 120384000 | V38: =G38*$Q38 -> 57 | W38: =Q38*H38 -> 60192000 | X38: =I38*$Q38 -> 34.2 | Y38: =Q38*J38 -> 36115200 | Z38: =K38*$Q38 -> 79.8 | AA38: =Q38*L38 -> 84268800 | AB38: =M38*$Q38 -> 266.76 | AC38: =Q38*N38 -> 281698560 | AD38: =O38*$Q38 -> 87.78 | AE38: =Q38*P38 -> 92695680
Q39: =SUM(Q33:Q38) -> 306 | R39: =SUM(R33:R38) -> 5660.49 | S39: =SUM(S33:S38) -> 5977477440 | T39: =SUM(T33:T38) -> 1009 | U39: =SUM(U33:U38) -> 1065504000 | V39: =SUM(V33:V38) -> 504.5 | W39: =SUM(W33:W38) -> 532752000 | X39: =SUM(X33:X38) -> 302.7 | ... AE39: =SUM(AE33:AE38) -> 820438080

Sheet 별첨.타사업사례
B2: 사업명 | C2: 사업비 | D2: 비고
B3: 18년 행안부 부평역 실내내비게이션 실증사업 | C3: 2 | D3: https://www.mediaic.co.kr/news/articleView.html?idxno=30354
B4: 21년(??) 서울시 고속터미널 센서수집 및 실내측위 실증
B5: 22년 행안부 잠실역 실내내비게이션 실증사업 | C5: 3.2 | D5: https://www.jeonmae.co.kr/news/articleView.html?idxno=863865
B6: 22년 대전시 신세계백화점 실내내비게이션 실증(4~5층) | C6: 0.5
B7: 23년 서초 고속터미널 지하상가 실내내비게이션 실증 | C7: 2 | D7: https://www.yna.co.kr/view/RPR20240110000700353
B8: 23년 대전시 입체공간기반 실내내비게이션 실증 | C8: 3
B9: 24년 인천공항 1터미널 실내내비게이션 실증 | C9: 4
B10: 22,23,24,25,26년 행안부 입체주소DB 구축사업 | D10: 매년60억
B11: 24,25,26,27년 행안부 입체주소 활용 센서맵DB 구축사업 | D11: 매년34억
B13: 센서맵기반 측위 vs 비콘기반 측위 비교자료

Sheet 별첨.안1 선정기준
A1: 장애인용 지하철 내비게이션 시범서비스 — 후보역 선정 매트릭스 (35개역 × 9개 기준)
A2: 등급: 상(우수)·중(보통)·하(낮음) / O(통과)·△(과대,구축부담주의) / —(미적용) ※기준3 위치분포 미적용 ※기준8 연면적=건물 총연면적(building_info 2026.05, 전 노선 포함), 적정≤22,000㎡·경계~40,000㎡·과대>40,000㎡
A3: 역 정보 | D3: 선정 여부 | E3: 기준1 이용률 | G3: 기준2 공간복잡도 | I3: 기준3 위치분포 | K3: 기준4 장애인수요 | M3: 기준5 시설확보 | O3: 기준6 환승역 | Q3: 기준7 장애인이용률 | S3: 기준8 연면적 | U3: 기준9 순수지하철역
A4: 순번 | B4: 역명 | C4: 환승노선 | D4: O/X | E4: 등급 | F4: 등급 근거 | G4: 등급 | H4: 등급 근거 | I4: 등급 | J4: 등급 근거 | K4: 등급 | L4: 등급 근거 | M4: 등급 | N4: 등급 근거 | O4: 등급 | P4: 등급 근거 | Q4: 등급 | R4: 등급 근거 | S4: 등급 | T4: 등급 근거 | U4: 등급 | V4: 등급 근거
A5: 1 | B5: 강남 | C5: 2·신분당 | D5: O | E5: 상 | F5: 일평균 14.9만명, 환승역 이용객 최상위권 | G5: 상 | H5: 2·신분당선 환승 + 대형 지하상가, 동선 분기 복잡 | I5: — | J5: 위치분포 기준 미적용 | K5: 상 | L5: 강남업무지구·병원·재활시설 밀집, 유동 수요 큼 | M5: 중 | N5: 엘리베이터·1동선 확보, 일부 출구 동선 길어 보완 여지 | O5: O | P5: 2·신분당선 환승역 | Q5: 상 | R5: 우대권 이용 상위, 유동 장애인 통행 많음 | S5: △ | T5: 71,993㎡ · 과대(>40k)·규모 큼, 현장 구축 부담 주의 | U5: O | V5: 지하상가 연결, 백화점 본체 미연결
A6: 3 | B6: 선릉 | C6: 2·수인분당 | D6: O | E6: 상 | F6: 일평균 12만명 이상, 업무지구 이용 상위 | G6: 중 | H6: 2·수인분당선 환승, 동선 보통 | I6: — | J6: 위치분포 기준 미적용 | K6: 중 | L6: 업무지구 근로 장애인 수요 | M6: 중 | N6: 엘리베이터 확보, 동선 보통 | O6: O | P6: 2·수인분당선 환승역 | Q6: 중 | R6: 우대권 이용 중상위 | S6: O | T6: 26,524㎡ · 경계 (적정≤22k/경계≤40k) | U6: O | V6: 지하상가 연결, 백화점 본체 미연결
A7: 4 | B7: 교대 | C7: 2·3 | D7: O | E7: 상 | F7: 일평균 9만명대, 강남권 핵심 환승 | G7: 중 | H7: 2·3호선 십자형 환승, 구조 명확 | I7: — | J7: 위치분포 기준 미적용 | K7: 상 | L7: 법조타운·공공기관, 민원 이동약자 수요 | M7: 상 | N7: 1동선 확보, 적정 동선 | O7: O | P7: 2·3호선 환승역 | Q7: 중 | R7: 우대권 이용 중상위 | S7: O | T7: 32,603㎡ · 경계 (적정≤22k/경계≤40k) | U7: O | V7: 소규모 지하상가만 연결
A8: 5 | B8: 이수(총신대입구) | C8: 4·7 | D8: O | E8: 중 | F8: 일평균 6만명대 | G8: 상 | H8: 4·7호선 환승거리 길어 복잡도 높음 | I8: — | J8: 위치분포 기준 미적용 | K8: 중 | L8: 주거·상업 혼재 수요 | M8: 상 | N8: 1동선 확보, 시설 양호 | O8: O | P8: 4·7호선 환승역 | Q8: 중 | R8: 우대권 이용 중위 | S8: O | T8: 29,975㎡ · 경계 (적정≤22k/경계≤40k) | U8: O | V8: 순수 지하철역
A9: 6 | B9: 동작 | C9: 4·9 | D9: O | E9: 하 | F9: 일평균 4만명대 | G9: 중 | H9: 4·9호선 환승, 동선 보통 | I9: — | J9: 위치분포 기준 미적용 | K9: 중 | L9: 현충원·보훈 연계 고령·이동약자 수요 | M9: 중 | N9: 엘리베이터 확보 | O9: O | P9: 4·9호선 환승역 | Q9: 중 | R9: 보훈 연계 우대권 수요 | S9: △ | T9: 42,288㎡ · 과대(>40k)·규모 큼, 현장 구축 부담 주의 | U9: O | V9: 순수 지하철역
A10: 8 | B10: 종로3가 | C10: 1·3·5 | D10: O | E10: 상 | F10: 일평균 9만명대, 3개 노선 환승 | G10: 상 | H10: 1·3·5호선, 1↔5호선 환승통로 312m | I10: — | J10: 위치분포 기준 미적용 | K10: 상 | L10: 고령자·전통상권 이용약자 수요 큼 | M10: 중 | N10: 2024년 엘리베이터 완공, 동선 김 | O10: O | P10: 1·3·5호선 환승역 | Q10: 상 | R10: 경로·우대권 이용 최상위(고령 상권) | S10: △ | T10: 41,298㎡ · 과대(>40k)·규모 큼, 현장 구축 부담 주의 | U10: O | V10: 익선동 등 지하상가 연결
A11: 9 | B11: 충무로 | C11: 3·4 | D11: O | E11: 중 | F11: 일평균 7만명대 | G11: 중 | H11: 3·4호선 환승, 동선 보통 | I11: — | J11: 위치분포 기준 미적용 | K11: 중 | L11: 국립극장·남산 연계 수요 | M11: 중 | N11: 엘리베이터 확보 | O11: O | P11: 3·4호선 환승역 | Q11: 중 | R11: 우대권 이용 중위 | S11: O | T11: 22,277㎡ · 경계 (적정≤22k/경계≤40k) | U11: O | V11: 순수 지하철역
A12: 10 | B12: 동대문 | C12: 1·4 | D12: O | E12: 중 | F12: 일평균 6만명대 | G12: 중 | H12: 1·4호선 환승 | I12: — | J12: 위치분포 기준 미적용 | K12: 중 | L12: 전통시장·관광 연계 수요 | M12: 중 | N12: 엘리베이터 확보 | O12: O | P12: 1·4호선 환승역 | Q12: 중 | R12: 우대권 이용 중위 | S12: O | T12: 22,408㎡ · 경계 (적정≤22k/경계≤40k) | U12: O | V12: 순수 지하철역(쇼핑몰 본체 미연결)
A13: 13 | B13: 신당 | C13: 2·6 | D13: O | E13: 중 | F13: 일평균 5만명대 | G13: 중 | H13: 2·6호선 환승 | I13: — | J13: 위치분포 기준 미적용 | K13: 중 | L13: 중앙시장·주거 수요 | M13: 상 | N13: 1동선 확보, 시설 양호 | O13: O | P13: 2·6호선 환승역 | Q13: 중 | R13: 우대권 이용 중위 | S13: O | T13: 34,930㎡ · 경계 (적정≤22k/경계≤40k) | U13: O | V13: 순수 지하철역
A14: 18 | B14: 건대입구 | C14: 2·7 | D14: O | E14: 상 | F14: 일평균 9만명대 | G14: 상 | H14: 2·7호선 환승, 휠체어 환승 35분→개선 대상 | I14: — | J14: 위치분포 기준 미적용 | K14: 중 | L14: 대학·상권 유동 수요 | M14: 상 | N14: 1동선 확보, 개선 사업 진행 | O14: O | P14: 2·7호선 환승역 | Q14: 중 | R14: 우대권 이용 중상위 | S14: O | T14: 19,377㎡ · 적정 (적정≤22k/경계≤40k) | U14: O | V14: 순수 지하철역(쇼핑몰 본체 미연결)
A15: 25 | B15: 합정 | C15: 2·6 | D15: O | E15: 상 | F15: 일평균 8만명대, 상권 거점 | G15: 중 | H15: 2·6호선 환승 | I15: — | J15: 위치분포 기준 미적용 | K15: 중 | L15: 상권·관광 유동 수요 | M15: 중 | N15: 엘리베이터 확보 | O15: O | P15: 2·6호선 환승역 | Q15: 중 | R15: 우대권 이용 중위 | S15: O | T15: 21,449㎡ · 적정 (적정≤22k/경계≤40k) | U15: O | V15: 순수 지하철역(쇼핑몰 본체 미연결)
A16: 31 | B16: 신림 | C16: 2·신림 | D16: O | E16: 상 | F16: 일평균 7만명대 | G16: 중 | H16: 2호선·신림선 환승 | I16: — | J16: 위치분포 기준 미적용 | K16: 중 | L16: 주거·상권 유동 수요 | M16: 중 | N16: 신림선 신설 환승, 엘리베이터 확보 | O16: O | P16: 2·신림선 환승역 | Q16: 중 | R16: 우대권 이용 중상위 | S16: O | T16: 14,705㎡ · 적정 (적정≤22k/경계≤40k) | U16: O | V16: 순수 지하철역
... A23: 17 | B23: 왕십리 | C23: 2·5·수인분당·경의중앙 | D23: X | E23: 중 | F23: 일평균 7만명대 | G23: 상 | H23: 4개 노선 환승, 동선 검증가치 최상 | I23: — | J23: 위치분포 기준 미적용 | K23: 중 | L23: 광역환승 연계 수요 | M23: 상 | N23: 광역환승센터, 1동선 확보 | O23: O | P23: 2·5·수인분당·경의중앙 환승역 | Q23: 중 | R23: 우대권 이용 중위 | S23: △ | T23: 108,489㎡ · 과대(>40k)·규모 큼, 현장 구축 부담 주의 | U23: O | V23: 순수 지하철역(민자 연결부 회피 가능)
A24: 14 | B24: 청구 | C24: 5·6 | E24: 하 | F24: 일평균 3만명대 | G24: 중 | H24: 5·6호선 환승 | I24: — | J24: 위치분포 기준 미적용 | K24: 중 | L24: 주거지 생활 수요 | M24: 중 | N24: 엘리베이터 확보 | O24: O | P24: 5·6호선 환승역 | Q24: 중 | R24: 우대권 이용 중위 | S24: O | T24: 26,963㎡ · 경계 (적정≤22k/경계≤40k) | U24: O | V24: 순수 지하철역
A25: 15 | B25: 약수 | C25: 3·6 | E25: 하 | F25: 일평균 4만명대 | G25: 중 | H25: 3·6호선 환승 | I25: — | J25: 위치분포 기준 미적용 | K25: 중 | L25: 주거지 생활 수요 | M25: 상 | N25: 신축급 시설, 1동선 확보 | O25: O | P25: 3·6호선 환승역 | Q25: 중 | R25: 우대권 이용 중위 | S25: O | T25: 21,599㎡ · 적정 (적정≤22k/경계≤40k) | U25: O | V25: 순수 지하철역
A26: 16 | B26: 삼각지 | C26: 4·6 | E26: 하 | F26: 일평균 4만명대 | G26: 중 | H26: 4·6호선 환승 | I26: — | J26: 위치분포 기준 미적용 | K26: 중 | L26: 전쟁기념관·보훈 연계 수요 | M26: 중 | N26: 엘리베이터 확보 | O26: O | P26: 4·6호선 환승역 | Q26: 중 | R26: 보훈 연계 우대권 수요 | S26: O | T26: 35,045㎡ · 경계 (적정≤22k/경계≤40k) | U26: O | V26: 순수 지하철역
A27: 19 | B27: 군자 | C27: 5·7 | E27: 중 | F27: 일평균 5만명대 | G27: 중 | H27: 5·7호선 환승 | I27: — | J27: 위치분포 기준 미적용 | K27: 중 | L27: 주거지 생활 수요 | M27: 중 | N27: 엘리베이터 확보 | O27: O | P27: 5·7호선 환승역 | Q27: 중 | R27: 우대권 이용 중위 | S27: O | T27: 24,848㎡ · 경계 (적정≤22k/경계≤40k) | U27: O | V27: 순수 지하철역
A28: 20 | B28: 노원 | C28: 4·7 | E28: 상 | F28: 일평균 9만명대, 동북부 거점 | G28: 상 | H28: 4·7호선 환승, 외부 이동 동선 복잡(개선 대상) | I28: — | J28: 위치분포 기준 미적용 | K28: 상 | L28: 동북부 주거 밀집, 이동약자 수요 큼 | M28: 상 | N28: 노후 에스컬레이터 교체 완료, 1동선 확보 | O28: O | P28: 4·7호선 환승역 | Q28: 상 | R28: 주거 밀집 우대권 이용 상위 | S28: O | T28: 24,492㎡ · 경계 (적정≤22k/경계≤40k) | U28: O | V28: 백화점 본체 미연결(별동)
A29: 21 | B29: 석계 | C29: 1·6 | E29: 중 | F29: 일평균 5만명대 | G29: 중 | H29: 1·6호선 입체 환승 | I29: — | J29: 위치분포 기준 미적용 | K29: 중 | L29: 주거·대학 연계 수요 | M29: 상 | N29: 1동선 확보, 시설 양호 | O29: O | P29: 1·6호선 환승역 | Q29: 중 | R29: 우대권 이용 중위 | S29: O | T29: 22,184㎡ · 경계 (적정≤22k/경계≤40k) | U29: O | V29: 순수 지하철역
A30: 22 | B30: 태릉입구 | C30: 6·7 | E30: 하 | F30: 일평균 4만명대 | G30: 중 | H30: 6·7호선 환승 | I30: — | J30: 위치분포 기준 미적용 | K30: 중 | L30: 주거지 생활 수요 | M30: 중 | N30: 엘리베이터 확보 | O30: O | P30: 6·7호선 환승역 | Q30: 중 | R30: 우대권 이용 중위 | S30: O | T30: 33,649㎡ · 경계 (적정≤22k/경계≤40k) | U30: O | V30: 순수 지하철역
A31: 23 | B31: 신설동 | C31: 1·2·우이신설 | E31: 중 | F31: 일평균 5만명대, 3개 노선 | G31: 상 | H31: 1·2(성수지선)·우이신설 3노선 환승 | I31: — | J31: 위치분포 기준 미적용 | K31: 중 | L31: 주거·상권 수요 | M31: 중 | N31: 2025년 1동선 완공 | O31: O | P31: 1·2·우이신설 환승역 | Q31: 중 | R31: 우대권 이용 중위 | S31: O | T31: 25,035㎡ · 경계 (적정≤22k/경계≤40k) | U31: O | V31: 순수 지하철역
A32: 24 | B32: 신촌 | C32: 2·경의중앙 | E32: 상 | F32: 일평균 8만명대, 대학가 | G32: 중 | H32: 2호선·경의중앙선 환승(지상-지하) | I32: — | J32: 위치분포 기준 미적용 | K32: 중 | L32: 대학·상권 유동 수요 | M32: 중 | N32: 엘리베이터 확보 | O32: O | P32: 2·경의중앙선 환승역 | Q32: 중 | R32: 우대권 이용 중위 | S32: O | T32: 31,458㎡ · 경계 (적정≤22k/경계≤40k) | U32: O | V32: 순수 지하철역
A33: 26 | B33: DMC | C33: 6·경의중앙·공항철도 | E33: 중 | F33: 일평균 6만명대, 3개 노선 | G33: 상 | H33: 3개 노선 환승, 광역 거점 | I33: — | J33: 위치분포 기준 미적용 | K33: 중 | L33: 미디어단지 근로 수요 | M33: 상 | N33: 1동선 확보, 시설 양호 | O33: O | P33: 6·경의중앙·공항철도 환승역 | Q33: 중 | R33: 우대권 이용 중위 | S33: △ | T33: 57,860㎡ · 과대(>40k)·규모 큼, 현장 구축 부담 주의 | U33: O | V33: 순수 지하철역(상암 빌딩군 별동)
A34: 27 | B34: 불광 | C34: 3·6 | E34: 중 | F34: 일평균 5만명대, 서북권 거점 | G34: 중 | H34: 3·6호선 환승 | I34: — | J34: 위치분포 기준 미적용 | K34: 중 | L34: 주거지 생활 수요 | M34: 상 | N34: 1동선 확보, 적정 동선 | O34: O | P34: 3·6호선 환승역 | Q34: 중 | R34: 우대권 이용 중위 | S34: O | T34: 21,564㎡ · 적정 (적정≤22k/경계≤40k) | U34: O | V34: 순수 지하철역
A35: 28 | B35: 연신내 | C35: 3·6 | E35: 중 | F35: 일평균 6만명대, 서북권 거점 | G35: 중 | H35: 3·6호선 환승 | I35: — | J35: 위치분포 기준 미적용 | K35: 중 | L35: 주거 밀집 생활 수요 | M35: 상 | N35: 1동선 확보, 시설 양호 | O35: O | P35: 3·6호선 환승역 | Q35: 중 | R35: 주거 밀집 우대권 이용 중상위 | S35: O | T35: 19,907㎡ · 적정 (적정≤22k/경계≤40k) | U35: O | V35: 순수 지하철역
... A39: 33 | B39: 가산디지털단지 | C39: 1·7 | E39: 상 | F39: 일평균 9만명대, IT 거점 | G39: 상 | H39: 1·7호선 환승, 단지 연계 동선 복잡 | I39: — | J39: 위치분포 기준 미적용 | K39: 상 | L39: IT 직장인 거점, 청장년 장애인 근로 수요 | M39: 상 | N39: 1동선 확보, 개선 진행 | O39: O | P39: 1·7호선 환승역 | Q39: 중 | R39: 근로 장애인 우대권 이용 중상위 | S39: O | T39: 24,205㎡ · 경계 (적정≤22k/경계≤40k) | U39: O | V39: 아울렛 본체 미연결(별동)

Sheet 별첨.안1선정근거자료
A1: 선정 기준별 근거자료 (기준 8 연면적 기준 채택)
A3: 기준 1. 이용률
A4: 근거자료: 서울교통공사 권종별 승차인원 (2024년 12월 기준)
A5: 링크 | B5: https://www.data.go.kr/data/15044254/fileData.do
A6: 출처 | B6: 서울교통공사 (공공데이터포털, ID 15044254)
A7: 내용 | B7: 선불·후불·정기권·우대권·1회권·단체권 등 권종별 승차인원을 월별·역별·호선별로 제공
A8: 활용 | B8: 역별 일평균 승하차 인원으로 이용률 상위 환승역 식별
A11: 기준 2. 공간복잡도 (동선 기준)
A12: 기준 8이 연면적(역 전체 크기)을 담당하므로, 기준 2는 환승 동선의 복잡성·길이로 역할을 명확히 분리합니다.
A13: 근거자료 ①: 서울시 환승거리·소요시간 측정자료
A14: 링크 | B14: https://www.asiae.co.kr/article/2015122108435802221
A15: 출처 | B15: 서울시의회 교통위원회 제출자료
A16: 내용 | B16: 환승시간 1위 홍대입구역(2호선→공항철도 355m), 2위 고속터미널역(7호선→9호선 314m). 노약자(장애인 포함)는 초당 1m로 산출
A18: 근거자료 ②: 종로3가역 환승통로 구조
A19: 링크 | B19: https://blog.hyundai-rotem.co.kr/209
A20: 내용 | B20: 1·3·5호선 교차, 1호선→5호선 환승통로 312m
A22: 근거자료 ③: 서울교통공사 역간거리 데이터
A23: 링크 | B23: https://data.seoul.go.kr/dataList/OA-12034/S/1/datasetView.do
A24: 내용 | B24: 1~8호선 역간 거리 및 소요시간 정보(2024.3.25 기준)
A27: 기준 3. 위치 분포
A28: 근거자료 ①: 서울시 장애인 현황 (장애유형별/동별)
A29: 링크 | B29: https://data.seoul.go.kr/dataList/10577/C/2/datasetView.do
A30: 출처 | B30: 서울특별시 장애인자립지원과
A31: 내용 | B31: 「장애인복지법」에 의거 자치구에 등록된 장애인 현황을 연령별·구별·행정동별로 제공, 매년 12월 기준 정기 공표
A33: 근거자료 ②: 서울교통공사 자치구별 지하철역 정보 (2026.2 기준)
A34: 링크 | B34: https://www.data.go.kr/data/15081868/fileData.do
A35: 내용 | B35: 자치구 30개별 역명·호선·역개수로 구성, 서울교통공사 관리 289개역 정보. 2026년 2월 기준 업데이트
A36: 활용 | B36: 권역 분류의 객관적 행정 기준
A39: 기준 4. 장애인 수요 적합성
A40: 근거자료 ①: 서울시 장애인 편의시설 통계
A41: 링크 | B41: https://data.seoul.go.kr/dataList/5/S/2/datasetView.do
A42: 출처 | B42: 서울특별시 장애인자립지원과
A43: 내용 | B43: 「편의증진법」 제11조에 근거하여 매개·내부·위생·안내시설 등 장애인 편의시설 설치 현황을 자치구별로 제공
A45: 근거자료 ②: 무의 서울지하철 교통약자 환승지도
A46: 링크 | B46: https://www.wearemuui.com/kr/seoulsubway-help
A47: 출처 | B47: 사단법인 무의
A48: 내용 | B48: 서울디자인재단의 서울지하철 환승·이동 정보체계 디자인 가이드에 따라 제작
A50: 근거자료 ③: 서울시 자치구별 도보 네트워크 공간정보
A51: 링크 | B51: https://data.seoul.go.kr/dataList/OA-21208/S/1/datasetView.do
A52: 활용 | B52: 역 주변 장애인 시설까지의 보행 접근성 분석
...
