Workbook

Sheet 요약
B2: 서울동행맵 고도화 — 테스트 케이스(TC) 전체
B4: 전체
B5: TC 총 건수 | C5: =COUNTA('TC 전체'!$B$2:$B$513) -> 512 | D5: 「TC 전체」 시트 행 수 — 정본 QA/tc/*.toml 16개 파일 합계
B6: 대상 화면 수 | C6: =SUMPRODUCT((매핑!$A$2:$A$1498="화면")/COUNTIFS(매핑!$A$2:$A$1498,매핑!$A$2:$A$1498,매핑!$B$2:$B$1498,매핑!$B$2:$B$1498)) -> 41 | D6: 화면 키 고유 개수(ID 부여 28 + 미부여 13)
B7: 커버 요건 수 | C7: =SUMPRODUCT((매핑!$A$2:$A$1498="요건")/COUNTIFS(매핑!$A$2:$A$1498,매핑!$A$2:$A$1498,매핑!$B$2:$B$1498,매핑!$B$2:$B$1498)) -> 135 | D7: TC가 1건 이상 걸린 PRD 요건 ID 개수
B9: 성격별
B10: 기능 | C10: =COUNTIF('TC 전체'!$F$2:$F$513,"기능") -> 269
B11: 접근성 | C11: =COUNTIF('TC 전체'!$F$2:$F$513,"접근성") -> 167
B12: 비기능 | C12: =COUNTIF('TC 전체'!$F$2:$F$513,"비기능") -> 47
B13: 시나리오 | C13: =COUNTIF('TC 전체'!$F$2:$F$513,"시나리오") -> 18
B14: 사용자평가 | C14: =COUNTIF('TC 전체'!$F$2:$F$513,"사용자평가") -> 1
B15: 대상외 | C15: =COUNTIF('TC 전체'!$F$2:$F$513,"대상외") -> 10
B17: 상태별
B18: 미실행 | C18: =COUNTIF('TC 전체'!$G$2:$G$513,"미실행") -> 427 | D18: 실행 전 초안 상태
B19: 보류 | C19: =COUNTIF('TC 전체'!$G$2:$G$513,"보류") -> 85 | D19: UX·PRD 사양이 갈려 합불을 가를 수 없는 항목
B21: 정본: QA/tc/*.toml (TOML) · 이 파일은 그 정본을 읽어 만든 생성물이며 여기서 편집한 값은 정본에 반영되지 않는다
B22: 생성 근거: scripts/check_tc.py 집계와 같은 정본 · RTM 열은 QA/generated/RTM.csv

Sheet TC 전체
A1: No | B1: TC ID | C1: 파일 | D1: 화면 | E1: 요건 | F1: 성격 | G1: 상태 | H1: 전제 | I1: 절차 | J1: 기대결과 | K1: KS | L1: 근거 | M1: 비고 | N1: 대상외 사유
A2: 1 | B2: TC-AUTH-01-01 | C2: 01-온보딩 | D2: AUTH-01 | E2: V-1 | F2: 기능 | G2: 미실행 | H2: iOS 단말 · 미인증 콜드 스타트로 앱 실행 | I2: 1. 앱을 실행해 로그인 화면에 진입 2. 소셜 로그인 버튼의 개수와 위에서 아래 순서를 기록 | J2: 소셜 로그인 버튼이 세로로 4개이고 순서가 카카오 → 네이버 → 구글 → 애플이다 | L2: UX 01-로그인-회원가입 2.3·2.4절 요소 4
A3: 2 | B3: TC-AUTH-01-02 | C3: 01-온보딩 | D3: AUTH-01 | E3: NFR-04 | F3: 접근성 | G3: 미실행 | H3: Android 단말 · TalkBack 켬 · 미인증 콜드 스타트 | I3: 1. 앱을 실행해 로그인 화면에 진입 2. 소셜 로그인 버튼 목록을 확인 3. 첫 버튼부터 다음 요소로 포커스를 순서대로 이동 | J3: 소셜 로그인 버튼이 카카오·네이버·구글 3개뿐이고 애플 자리에 빈 항목·비활성 버튼이 없으며 포커스가 그 자리를 지나가지 않는다 | L3: UX 01-로그인-회원가입 2.4절 요소 4 · 2.5절 NFR-04 플랫폼별 검증
A4: 3 | B4: TC-AUTH-01-03 | C4: 01-온보딩 | D4: AUTH-01 | E4: V-3 · NFR-05 | F4: 접근성 | G4: 미실행 | H4: 로그인 화면 진입 | I4: 1. 소셜 로그인 버튼 각각의 표시 내용을 확인 2. 각 버튼에 로고와 텍스트가 함께 있는지 기록 | J4: 각 버튼이 로고와 텍스트를 함께 갖고, 공급자를 브랜드 색만으로 구분하는 버튼이 하나도 없다 | L4: UX 01-로그인-회원가입 2.4절 요소 4 · 2.7절
A5: 4 | B5: TC-AUTH-01-04 | C5: 01-온보딩 | D5: AUTH-01 | E5: AC-05 · V-1 · NFR-04 | F5: 접근성 | G5: 미실행 | H5: 스크린리더 켬 · 로그인 화면 진입 | I5: 1. 화면 첫 요소에 포커스를 두고 끝까지 순서대로 이동 2. 낭독된 항목을 순서대로 기록 | J5: 서비스명 → 이용 방식 안내 1문장 → 로그인 수단 → 「비회원으로 시작하기」 순으로 낭독되고 중간에 건너뛰는 항목이 없다 | L5: UX 01-로그인-회원가입 2.5절 낭독 순서 · 00-공통 5절 | M5: 접근권한 고지는 U-25 미확정이라 이 TC의 판정 대상이 아니다
A6: 5 | B6: TC-AUTH-01-05 | C6: 01-온보딩 | D6: AUTH-01 | E6: NFR-05 | F6: 접근성 | G6: 미실행 | H6: 스크린리더 켬 · 로그인 화면 진입 | I6: 1. 카카오 로그인 버튼에 포커스 2. 낭독 문자열을 기록 3. 나머지 소셜 버튼에서 반복 | J6: 각 버튼이 "카카오로 로그인, 버튼"처럼 목적지를 담아 낭독되고, 공급자 이름만("카카오")으로 낭독되는 버튼이 없다 | L6: UX 01-로그인-회원가입 2.4절 요소 2·4 · 2.5절
A7: 6 | B7: TC-AUTH-01-06 | C7: 01-온보딩 | D7: AUTH-01 | E7: V-3 · V-6 | F7: 기능 | G7: 미실행 | H7: 공급자 인증이 실패하도록 준비한 환경 | I7: 1. 카카오 로그인 버튼을 누름 2. 인증 실패 후 앱으로 복귀 3. 실패 표기의 채널과 포커스 위치를 확인 | J7: 실패 사유가 색·텍스트·아이콘 3채널로 함께 표시되고 포커스가 소셜 로그인 버튼 묶음으로 복귀하며 재시도 수단이 남는다 | L7: UX 01-로그인-회원가입 2.4절 요소 8 · 2.8절 | M7: 공급자 인증 취소·서버 인증 실패도 같은 축이며 각각 구분되는 문구로 알린다(UX 2.8절)
A8: 7 | B8: TC-AUTH-01-07 | C8: 01-온보딩 | D8: AUTH-01 | E8: SG-3 · V-3 | F8: 접근성 | G8: 미실행 | H8: 로그인 화면 진입 | I8: 1. 소셜 로그인 버튼 묶음과 「비회원으로 시작하기」 사이의 구분 수단을 확인 2. 시스템 글자 크기를 200%로 올린 뒤 같은 지점을 다시 확인 | J8: 두 묶음의 위계가 구분선 또는 면 대비로 표시되고 200%에서도 구분이 유지된다. 간격만으로 위계를 나타내지 않는다 | L8: UX 01-로그인-회원가입 2.3절·2.7절 · PRD 2부 7.4 SG-3
A9: 8 | B9: TC-AUTH-01-08 | C9: 01-온보딩 | D9: AUTH-01 · AUTH-04 | E9: V-11 · V-13 | F9: 시나리오 | G9: 미실행 | H9: 비회원으로 교통약자 유형을 한 번 고른 단말 · 앱 데이터 삭제 없음 | I9: 1. 앱을 완전히 종료 2. 앱을 다시 실행해 「비회원으로 시작하기」를 누름 3. 다음에 뜨는 화면을 확인 | J9: 교통약자 유형 선택을 다시 묻지 않고 곧바로 홈으로 진입하며, 최초에 고른 유형이 그대로 적용돼 있다 | L9: UX 01-로그인-회원가입 2.4절 요소 5 · 6절 비회원 로컬 데이터의 수명과 재진입
A10: 9 | B10: TC-AUTH-01-09 | C10: 01-온보딩 | D10: AUTH-01 | E10: SS-2 | F10: 시나리오 | G10: 미실행 | H10: 회원으로 로그인된 단말 · 서버에서 해당 세션을 무효로 만들어 둔 상태 | I10: 1. 앱을 완전히 종료 2. 앱을 다시 실행 3. 진입 화면을 확인 | J10: 앱 실행 시점에 세션이 확인돼 무효로 판정되고 로그아웃 상태로 로그인 화면에 진입한다 | L10: PRD 2부 6.10 SS-2
A11: 10 | B11: TC-AUTH-01-10 | C11: 01-온보딩 | D11: AUTH-01 | E11: SS-1 · SS-3 | F11: 시나리오 | G11: 미실행 | H11: 같은 계정으로 단말 A에 로그인된 상태 · 단말 B 준비 | I11: 1. 단말 B에서 같은 계정으로 로그인 2. 단말 A의 앱을 완전히 종료했다가 다시 실행 3. 단말 A의 진입 화면을 확인 | J11: 단말 A가 로그아웃 상태로 로그인 화면에 진입한다. 두 단말의 세션이 동시에 유지되지 않는다 | L11: PRD 1부 1.6 다중 기기 동시 로그인 · PRD 2부 6.10 SS-1·SS-3 | M11: 비회원은 계정이 없어 세션이 성립하지 않으므로 이 판정의 대상이 아니다
A12: 11 | B12: TC-AUTH-01-11 | C12: 01-온보딩 | D12: AUTH-01 | E12: SS-4 | F12: 시나리오 | G12: 미실행 | H12: 단말 A에서 앱을 실행해 둔 상태 | I12: 1. 앱을 실행한 채로 단말 B에서 같은 계정으로 로그인 2. 단말 A를 종료하지 않고 계속 조작 3. 단말 A에서 강제 로그아웃·로그인 화면 전환이 일어나는지 확인 | J12: 단말 A는 실행 중 강제 로그아웃되지 않고 그대로 동작한다. 실시간 강제 로그아웃 채널이 동작하지 않는다 | L12: PRD 2부 6.10 SS-4 | M12: 실행 중 무효화를 감지하지 않는 것이 SS-4가 받아들이는 귀결이며 결함이 아니다
A13: 12 | B13: TC-AUTH-01-12 | C13: 01-온보딩 | D13: AUTH-01 | E13: SS-4 · V-6 | F13: 기능 | G13: 미실행 | H13: TC-AUTH-01-11의 상태(단말 A 실행 중 · 세션은 이미 무효) | I13: 1. 단말 A에서 인증이 필요한 동작을 수행해 API 인증 실패를 유발 2. 화면 표시와 낭독을 확인 | J13: 인증 실패가 화면에 드러난다. 사용자 모르게 로그아웃 상태가 되거나 조용히 실패하지 않는다 | L13: PRD 2부 6.10 SS-4 · 6.7 에러 핸들링 원칙
A14: 13 | B14: TC-AUTH-01-13 | C14: 01-온보딩 | D14: AUTH-01 | E14: SS-5 | F14: 대상외 | G14: 미실행 | L14: PRD 2부 6.10 SS-5 | M14: 앱 축에서 볼 것은 SS-2~SS-4의 동작뿐이며 그 3건은 TC-AUTH-01-09~12가 진다 | N14: 세션 체크 API·토큰 규격·인증 에러 코드는 PRD가 갖지 않고 SvrAPIDoc에 위임한 항목이다. 규격 자체의 검증은 서버 파트 소관이며 앱 TC로 판정할 대상이 아니다
A15: 14 | B15: TC-AUTH-04-01 | C15: 01-온보딩 | D15: AUTH-04 | E15: V-11 | F15: 기능 | G15: 미실행 | H15: 회원가입 STEP 1 진입 | I15: 1. 선택지 목록의 행 수와 각 행의 표시 문자열을 기록 2. 3·4번 행의 부기가 라벨과 같은 한 줄인지, 1·2번에 부기가 없는지 확인 3. 목록에 「나중에 선택」류의 보류 선택지가 있는지 확인 | J15: 선택지가 라디오 4행(휠체어•유모차 / 노약자•임산부 / 저시력 – 화면을 볼 수 있어요. / 전맹 – 화면을 볼 수 없어요.)이고 부기는 3·4번에만 라벨 한 줄로 붙으며 보류 선택지가 없다 | L15: UX 01-로그인-회원가입 3.2절·3.6절 · PRD 1부 1.3 교통약자 유형 선택 4종 | M15: UX 사양의 4종이 정본이다. PRD 1부 1.3도 2026-08-27 통합으로 4종이라 md끼리는 갈리지 않는다
A16: 15 | B16: TC-AUTH-04-02 | C16: 01-온보딩 | D16: AUTH-04 | E16: V-11 | F16: 기능 | G16: 미실행 | H16: 회원가입 STEP 1 진입 · 아직 아무것도 고르지 않은 상태 | I16: 1. 진입 직후 선택된 항목이 있는지 확인 2. 1번을 선택 3. 이어서 3번을 선택 4. 1번의 상태를 확인 | J16: 진입 시 선택된 항목이 없고, 3번을 고르면 1번이 자동 해제돼 항상 한 항목만 선택된다 | L16: UX 01-로그인-회원가입 3.6절·3.7절 요소 4
A17: 16 | B17: TC-AUTH-04-03 | C17: 01-온보딩 | D17: AUTH-04 | E17: V-11 · V-6 | F17: 기능 | G17: 미실행 | H17: 회원가입 STEP 1 진입 · 아직 아무것도 고르지 않은 상태 | I17: 1. 「다음」 버튼의 활성 여부를 확인 2. 「다음」을 눌러 진행을 시도 3. 유형 하나를 선택한 뒤 「다음」의 활성 여부를 다시 확인 | J17: 선택 전에는 「다음」이 비활성이라 진행되지 않고, 유형을 하나 선택하면 활성으로 바뀐다 | L17: UX 01-로그인-회원가입 3.7절 요소 6 · 3.10절
A18: 17 | B18: TC-AUTH-04-04 | C18: 01-온보딩 | D18: AUTH-04 | E18: V-6 · AC-05 | F18: 접근성 | G18: 미실행 | H18: 스크린리더 켬 · 회원가입 STEP 1 진입 · 아직 아무것도 고르지 않은 상태 | I18: 1. 비활성 상태의 「다음」 버튼에 포커스 2. 낭독 문자열을 기록 3. 화면에 표시된 버튼 문구를 기록 | J18: 낭독이 사용할 수 없음과 함께 무엇을 골라야 하는지 사유까지 전달하고, 화면 표시 문구는 「다음」으로 고정돼 사유로 바뀌지 않는다 | L18: UX 01-로그인-회원가입 3.7절 요소 6 · 00-공통 7절 | M18: 사유 문안은 기획 초안이며 검수 전이다
A19: 18 | B19: TC-AUTH-04-05 | C19: 01-온보딩 | D19: AUTH-04 | E19: V-3 | F19: 접근성 | G19: 미실행 | H19: 회원가입 STEP 1 진입 · 그레이스케일 표시로 전환한 단말 | I19: 1. 유형 하나를 선택 2. 그레이스케일 상태에서 선택된 항목과 선택되지 않은 항목을 구별할 수 있는지 확인 | J19: 라디오 표시 형태로 선택 항목이 구별된다. 색만으로 선택 상태를 전달하지 않는다 | L19: UX 01-로그인-회원가입 3.7절 요소 4 · 3.9절
A20: 19 | B20: TC-AUTH-04-06 | C20: 01-온보딩 | D20: AUTH-04 | E20: AC-05 · NFR-05 | F20: 접근성 | G20: 미실행 | H20: 스크린리더 켬 · 회원가입 STEP 1 진입 | I20: 1. 선택지 4행에 순서대로 포커스를 이동 2. 각 행의 낭독 문자열을 기록 | J20: 각 행이 라벨(부기 포함) + 라디오 버튼 + 선택 상태 순으로 낭독되고, 부기가 있는 3·4번은 부기까지 한 라벨로 읽힌다 | L20: UX 01-로그인-회원가입 3.7절 요소 4·5
A21: 20 | B21: TC-AUTH-04-07 | C21: 01-온보딩 | D21: AUTH-04 | E21: AC-05 | F21: 접근성 | G21: 미실행 | H21: 스크린리더 켬 · 회원가입 STEP 1 진입 | I21: 1. 선택지 4행의 낭독 문자열을 모두 기록 2. 진단 여부를 되묻는 의문문 형태가 있는지 확인 | J21: 모든 행이 상태 기술 + 역할 형태로 낭독되고 진단을 확인하는 의문문으로 읽히는 행이 없다 | L21: UX 01-로그인-회원가입 3.3절 · 3.7절 요소 4 낭독 주의
A22: 21 | B22: TC-AUTH-04-08 | C22: 01-온보딩 | D22: AUTH-04 | E22: SG-1 · V-1 | F22: 접근성 | G22: 미실행 | H22: 스크린리더 켬 · 회원가입 STEP 1 진입 | I22: 1. 화면에서 선택지가 시각적으로 묶여 보이는 단위를 기록 2. 스크린리더로 같은 구간을 통과하며 그룹 경계가 전달되는지 확인 | J22: 시각적으로 묶인 단위에 대응하는 그룹 구조가 스크린리더에도 존재한다. 시각 채널에만 있는 그루핑이 없다 | L22: PRD 2부 7.4 SG-1 · UX 01-로그인-회원가입 3.6절·3.9절 | M22: 그룹 라벨을 화면에 노출하지 않는 것은 허용된다. 스크린리더에 그룹이 존재하는지가 판정 기준이다
A23: 22 | B23: TC-AUTH-04-09 | C23: 01-온보딩 | D23: AUTH-04 | E23: SG-2 | F23: 기능 | G23: 미실행 | H23: 유형별로 온보딩을 4회 반복 수행할 수 있는 단말 | I23: 1. 1번 휠체어•유모차를 골라 온보딩을 끝내고 진입한 화면 세트를 기록 2. 앱 데이터를 지우고 2번 노약자•임산부로 반복 3. 같은 방식으로 3번 저시력, 4번 전맹으로 반복 4. 4회 결과의 화면 세트를 대조 | J23: 선택지는 4종이지만 화면 세트는 S1과 S2 두 벌뿐이다. 1·2·3번이 같은 S1 화면 세트이고 4번만 S2다 | L23: PRD 2부 7.4 SG-2 · UX 01-로그인-회원가입 3.2절 3분류 표 | M23: 선택지 수를 화면 세트 수로 읽는 것이 SG-2가 막는 실패 모드다
A24: 23 | B24: TC-AUTH-04-10 | C24: 01-온보딩 | D24: AUTH-04 | E24: SG-3 · AC-06 · T-4 | F24: 비기능 | G24: 미실행 | H24: 회원가입 STEP 1 진입 | I24: 1. 질문·선택지 목록·하단 버튼 묶음의 구분 수단을 기록 2. 시스템 글자 크기를 200%로 올린 뒤 같은 구간을 다시 확인 | J24: 묶음 구분이 구분선·면 대비 등 간격 외의 수단으로도 유지되고 200%에서 덩이가 뭉개지지 않는다 | L24: PRD 2부 7.4 SG-3 · UX 01-로그인-회원가입 3.6절
A25: 24 | B25: TC-AUTH-04-11 | C25: 01-온보딩 | D25: AUTH-04 | E25: SG-4 | F25: 시나리오 | G25: 미실행 | H25: 3번 저시력으로 온보딩을 끝내고 로그인된 상태 | I25: 1. 마이페이지의 교통약자 유형 변경으로 진입 2. 선택지 구성을 최초 온보딩과 대조 3. 다른 유형으로 바꾼 뒤 저장 결과를 확인 | J25: 재선택 경로에서 최초와 같은 4종이 제공되고 유형을 바꿀 수 있다. 최초 선택이 사용자를 한 분류에 고정하지 않는다 | L25: PRD 2부 7.4 SG-4 · UX 01-로그인-회원가입 3.1절 재선택 조항 | M25: 중복 장애 사용자 대응은 복수 선택이 아니라 이 사후 변경 경로가 담당한다
A26: 25 | B26: TC-AUTH-04-12 | C26: 01-온보딩 | D26: AUTH-04 | E26: SG-6 | F26: 시나리오 | G26: 미실행 | H26: 1번 휠체어•유모차로 온보딩을 끝낸 상태 | I26: 1. 마이페이지에서 글자 크기를 확대로 바꿈 2. 교통약자 유형이 1번 그대로인지 확인 3. 유형을 3번 저시력으로 바꾼 뒤 글자 크기 설정값이 유지되는지 확인 | J26: 이동 축(유형)과 시각 축(글자 크기)이 서로를 덮어쓰지 않고 각각 독립으로 유지된다 | L26: PRD 2부 7.4 SG-6
A27: 26 | B27: TC-AUTH-04-13 | C27: 01-온보딩 | D27: AUTH-04 | E27: SG-7 | F27: 시나리오 | G27: 미실행 | H27: 1번 휠체어•유모차와 2번 노약자•임산부로 각각 온보딩을 끝낸 단말 2대 또는 초기화 2회 | I27: 1. 두 경우의 온보딩 직후 홈 화면 구성을 나란히 기록 2. 두 화면의 요소 종류·개수·배치를 대조 | J27: 이동 축이 갈려도 화면 세트는 같다. 유형에 따라 별도 화면 벌이 추가되지 않는다 | L27: PRD 2부 7.4 SG-7 · PRD 1부 1.3 선택 UI 4개·구현 2축 | M27: 이동 축이 갈리는 자리는 경로 산출·동선·안내 문안이며 그 검증은 길안내 화면 TC가 진다
A28: 27 | B28: TC-AUTH-04-14 | C28: 01-온보딩 | D28: AUTH-04 | E28: V-11 | F28: 기능 | G28: 미실행 | H28: 회원가입 STEP 1 진입 | I28: 1. 3번 저시력을 선택하고 「다음」을 누름 2. 온보딩을 끝내고 홈에 진입해 본문 글자 크기 상태를 확인 3. 마이페이지에서 글자 크기 조절 지점이 있는지 확인 | J28: 글자 크기 초기값이 확대로 적용되고, 조절 지점은 마이페이지에 그대로 있다. 이 선택지가 조절 지점을 대체하지 않는다 | L28: UX 01-로그인-회원가입 3.2절·3.4절 · PRD 1부 1.3 유형 표 3번
A29: 28 | B29: TC-AUTH-04-15 | C29: 01-온보딩 | D29: AUTH-04 | E29: V-11 | F29: 기능 | G29: 미실행 | H29: 회원가입 STEP 1 진입 | I29: 1. 4번 전맹을 선택 2. 「다음」을 누름 3. 다음에 표시되는 단계를 기록 | J29: 닉네임 입력 단계를 건너뛰고 남은 단계로 이동한다. 중간에 별도의 음성 안내 전용 단계가 삽입되지 않는다 | L29: UX 01-로그인-회원가입 1절 STEP 표 · 3.5절 이탈
A30: 29 | B30: TC-AUTH-04-16 | C30: 01-온보딩 | D30: AUTH-04 | E30: AC-05 · V-6 | F30: 접근성 | G30: 보류 | H30: 스크린리더 켬 · 회원가입 STEP 1 진입 | I30: 1. 4번 전맹에 포커스해 낭독을 기록 2. 4번을 선택한 뒤 낭독을 기록 | J30: 사양이 갈린다. UX 3.7절은 전맹 선택 시 다음 단계가 음성 안내로 바뀐다는 예고를 낭독할지를 ⬜ 미확정으로 두면서 「화면 성격이 바뀌는 전환이므로 예고하는 쪽이 안전하다」고만 적고 문안을 작성하지 않았다. 예고 낭독의 유무·문안이 정해질 때까지 합불을 가를 수 없다 | L30: UX 01-로그인-회원가입 3.7절 요소 5 · 3.11절 미확정 | M30: U-116 문안 미작성 — 기획 소관. 문안이 확정되면 낭독 유무와 문자열을 판정 기준으로 바꾼다
A31: 30 | B31: TC-AUTH-04-17 | C31: 01-온보딩 | D31: AUTH-04 | E31: NFR-04 · V-6 | F31: 기능 | G31: 보류 | H31: 3번 저시력으로 온보딩을 끝낸 상태 · 마이페이지의 교통약자 유형 변경 진입 | I31: 1. 4번 전맹으로 바꿈 2. 확인 단계가 뜨는지와 몇 단계인지 기록 3. 확인 문안과 낭독을 기록 | J31: 사양이 갈린다. UX 3.10절은 전맹 선택·해제에 확인 단계를 둔다고 요건화했으나 확인 문안·단계 수·낭독 문안이 ⬜ 미작성이다. 확인 단계의 존재만으로는 합불을 가를 수 없다 | L31: UX 01-로그인-회원가입 3.10절 「재선택으로 스킨이 바뀜」 | M31: 확인 단계를 두는 것 자체는 확정이다. 미확정은 문안·단계 수이며 기획 소관
A32: 31 | B32: TC-AUTH-04-18 | C32: 01-온보딩 | D32: AUTH-04 | E32: V-6 | F32: 기능 | G32: 미실행 | H32: 회원가입 STEP 1 진입 · 통신을 끊을 수 있는 환경 | I32: 1. 유형 하나를 선택 2. 통신을 끊은 상태에서 「다음」을 누름 3. 선택값이 유지되는지 확인 4. 통신을 복구한 뒤 계정에 동기화되는지 확인 | J32: 통신이 끊겨도 선택이 로컬에 유지되고 복구 시 계정에 동기화된다. 선택이 사라진 것처럼 보이지 않는다 | L32: UX 01-로그인-회원가입 3.10절 「저장 실패(통신 두절)」
A33: 32 | B33: TC-AUTH-04-19 | C33: 01-온보딩 | D33: AUTH-04 | E33: NFR-04 | F33: 기능 | G33: 보류 | H33: 회원가입 STEP 1 진입 · 아직 아무것도 고르지 않은 상태 | I33: 1. 「이전으로」를 누름 2. 도착한 화면을 기록 3. 다시 STEP 1로 돌아와 진행 상태가 남아 있는지 확인 | J33: 사양이 갈린다. UX 3.10절이 온보딩 첫 단계에서 「이전으로」의 목적지와 그때 진행 상태가 남는지를 ⬜ 미확정(U-66)으로 두고 있어 도착 화면·상태 보존 여부의 합불을 가를 수 없다 | L33: UX 01-로그인-회원가입 3.10절 「선택하지 않고 뒤로 나감」 | M33: U-66 — 기획 소관
A34: 33 | B34: TC-AUTH-04-20 | C34: 01-온보딩 | D34: AUTH-04 | E34: NFR-02 · S-1 · S-2 | F34: 비기능 | G34: 미실행 | H34: 회원가입 STEP 1 진입 · 측정 도구 준비 | I34: 1. 선택지 4행 각각의 히트 영역을 측정 2. 인접한 행 사이 간격과 하단 두 버튼 사이 간격을 측정 | J34: 선택지 행과 하단 버튼의 히트 영역이 44×44pt 이상이고 인접 간격이 8px 이상이다 | L34: UX 01-로그인-회원가입 3.9절 · PRD 2부 7.8 S-1·S-2
A35: 34 | B35: TC-AUTH-04-21 | C35: 01-온보딩 | D35: AUTH-04 | E35: NFR-04 · AC-05 | F35: 접근성 | G35: 미실행 | H35: 스크린리더 켬 · 회원가입 STEP 1 진입 · 포인팅 없이 포커스 이동만 사용 | I35: 1. 화면 첫 요소부터 마지막 요소까지 포커스를 순서대로 이동해 순서를 기록 2. 포커스 상태에서 누르기만으로 유형 선택과 「다음」 진행을 수행 | J35: 제목 → 스텝 인디케이터 → 질문 → 선택지 4행 → 「다음」 → 「이전으로」 순으로 포커스가 이동하고, 누르기만으로 선택과 진행이 모두 가능하다 | L35: UX 01-로그인-회원가입 3.6절·3.7절 · 00-공통 5절
A36: 35 | B36: TC-AUTH-04-22 | C36: 01-온보딩 | D36: AUTH-04 | E36: AC-06 · T-4 | F36: 비기능 | G36: 미실행 | H36: 4번 전맹으로 온보딩을 끝낸 상태(S2) · 시스템 글자 크기 200% | I36: 1. 마이페이지에서 글자 크기 조절 단이 제공되는지 확인 2. 시스템 글자 크기 200% 상태에서 화면 텍스트 크기와 레이아웃을 확인 | J36: 전맹에는 앱의 글자 크기 조절 단이 없고, 그럼에도 시스템 배율 200%가 그대로 적용되며 레이아웃이 깨지지 않는다 | L36: UX 01-로그인-회원가입 3.2절·3.4절 · PRD 2부 7.3 T-4 | M36: 앱 크기 축이 없는 것과 시스템 배율이 적용되지 않는 것은 다르다
A37: 36 | B37: TC-AUTH-03-01 | C37: 01-온보딩 | D37: AUTH-03 | E37: V-1 | F37: 기능 | G37: 미실행 | H37: 로그인 화면에서 회원가입을 선택 | I37: 1. STEP 1부터 완료까지 진행하며 거치는 단계를 기록 2. 마지막 단계의 완료 버튼 문구를 기록 | J37: 회원가입이 교통약자 유형 → 닉네임 → 약관 동의 3단계이고 마지막 단계 버튼이 「시작하기」다 | L37: UX 01-로그인-회원가입 1절 전체 흐름·STEP 표
A38: 37 | B38: TC-AUTH-03-02 | C38: 01-온보딩 | D38: AUTH-03 · AUTH-04 | E38: V-13 | F38: 기능 | G38: 미실행 | H38: 앱 데이터가 없는 단말 · 로그인 화면에서 「비회원으로 시작하기」를 누름 | I38: 1. 상단 제목 문자열을 기록 2. 스텝 인디케이터의 유무를 확인 3. 하단 완료 버튼 문구를 기록 4. 완료 후 도착 화면을 기록 | J38: 제목이 「정보 입력」이고 스텝 인디케이터가 없으며 완료 버튼이 「시작하기」이고, 누르면 홈으로 진입한다 | L38: UX 01-로그인-회원가입 1절 · 2.8절 「비회원 선택」 · 3.7절 요소 1·2 | M38: U-61 — 비회원 진입 화면에 별도 화면 ID를 줄지 미확정이다. 부여되면 이 TC의 화면 키를 이관한다
A39: 38 | B39: TC-AUTH-03-03 | C39: 01-온보딩 | D39: AUTH-03 · AUTH-04 | E39: V-13 · V-14 | F39: 기능 | G39: 미실행 | H39: 로그인 화면에서 「비회원으로 시작하기」를 누름 | I39: 1. 교통약자 유형을 하나 선택하고 「시작하기」를 누름 2. 닉네임 입력 단계와 약관 동의 단계가 나타나는지 확인 3. 홈 진입 후 닉네임 표기를 확인 | J39: 비회원은 교통약자 유형만 받고 닉네임 입력·약관 동의 단계에 도달하지 않으며 닉네임이 시스템에서 자동 부여돼 있다 | L39: UX 01-로그인-회원가입 1절 STEP 표 · 5.1절·5.2절 · PRD 2부 7.4 V-13
A40: 39 | B40: TC-AUTH-03-04 | C40: 01-온보딩 | D40: AUTH-03 | E40: V-13 | F40: 기능 | G40: 보류 | H40: 비회원으로 시작하는 흐름 진입 | I40: 1. 비회원 흐름 전체에서 위치기반 서비스 약관 동의를 받는 지점이 있는지 확인 2. 약관 3종의 열람 경로가 제공되는지 확인 | J40: 사양이 갈린다. 현행 UX·PRD는 비회원에게 약관 동의를 받지 않는 것으로 확정돼 있으나, 비회원 위치기반 약관 동의의 법령 근거가 열린 미결(PM → 법무·발주처)이고 결과가 반대면 비회원 전용 약관 1종이 추가된다. 동의 지점의 유무를 지금 합불로 가를 수 없다 | L40: UX 01-로그인-회원가입 2.6절 입력 · 5.6절 입력 | M40: 동의를 받지 않는 것과 문서를 감추는 것은 다르다 — 약관 열람 경로는 비회원에게도 제공된다. 그 부분은 확정 사양이다
...

Sheet 매핑
A1: 축 | B1: 키 | C1: TC ID | D1: 성격 | E1: 상태
A2: 화면 | B2: AUTH-01 | C2: TC-AUTH-01-01 | D2: 기능 | E2: 미실행
A3: 요건 | B3: V-1 | C3: TC-AUTH-01-01 | D3: 기능 | E3: 미실행
A4: 화면 | B4: AUTH-01 | C4: TC-AUTH-01-02 | D4: 접근성 | E4: 미실행
A5: 요건 | B5: NFR-04 | C5: TC-AUTH-01-02 | D5: 접근성 | E5: 미실행
A6: 화면 | B6: AUTH-01 | C6: TC-AUTH-01-03 | D6: 접근성 | E6: 미실행
A7: 요건 | B7: V-3 | C7: TC-AUTH-01-03 | D7: 접근성 | E7: 미실행
A8: 요건 | B8: NFR-05 | C8: TC-AUTH-01-03 | D8: 접근성 | E8: 미실행
A9: 화면 | B9: AUTH-01 | C9: TC-AUTH-01-04 | D9: 접근성 | E9: 미실행
A10: 요건 | B10: AC-05 | C10: TC-AUTH-01-04 | D10: 접근성 | E10: 미실행
A11: 요건 | B11: V-1 | C11: TC-AUTH-01-04 | D11: 접근성 | E11: 미실행
A12: 요건 | B12: NFR-04 | C12: TC-AUTH-01-04 | D12: 접근성 | E12: 미실행
... A1498: 요건 | B1498: L-8 | C1498: TC-FR-R3-00 | D1498: 기능 | E1498: 미실행

Sheet 화면별
A1: 화면 키 | B1: TC 건수 | C1: 미실행 | D1: 보류
A2: 1-2 | B2: =COUNTIFS(매핑!$A$2:$A$1498,"화면",매핑!$B$2:$B$1498,$A2) -> 11 | C2: =COUNTIFS(매핑!$A$2:$A$1498,"화면",매핑!$B$2:$B$1498,$A2,매핑!$E$2:$E$1498,"미실행") -> 10 | D2: =COUNTIFS(매핑!$A$2:$A$1498,"화면",매핑!$B$2:$B$1498,$A2,매핑!$E$2:$E$1498,"보류") -> 1
A3: 1-2-2 | B3: =COUNTIFS(매핑!$A$2:$A$1498,"화면",매핑!$B$2:$B$1498,$A3) -> 14 | C3: =COUNTIFS(매핑!$A$2:$A$1498,"화면",매핑!$B$2:$B$1498,$A3,매핑!$E$2:$E$1498,"미실행") -> 13 | D3: =COUNTIFS(매핑!$A$2:$A$1498,"화면",매핑!$B$2:$B$1498,$A3,매핑!$E$2:$E$1498,"보류") -> 1
A4: 1-2-3 | B4: =COUNTIFS(매핑!$A$2:$A$1498,"화면",매핑!$B$2:$B$1498,$A4) -> 14 | C4: =COUNTIFS(매핑!$A$2:$A$1498,"화면",매핑!$B$2:$B$1498,$A4,매핑!$E$2:$E$1498,"미실행") -> 13 | D4: =COUNTIFS(매핑!$A$2:$A$1498,"화면",매핑!$B$2:$B$1498,$A4,매핑!$E$2:$E$1498,"보류") -> 1
A5: 1-2-4 | B5: =COUNTIFS(매핑!$A$2:$A$1498,"화면",매핑!$B$2:$B$1498,$A5) -> 14 | C5: =COUNTIFS(매핑!$A$2:$A$1498,"화면",매핑!$B$2:$B$1498,$A5,매핑!$E$2:$E$1498,"미실행") -> 13 | D5: =COUNTIFS(매핑!$A$2:$A$1498,"화면",매핑!$B$2:$B$1498,$A5,매핑!$E$2:$E$1498,"보류") -> 1
A6: 1-2-6 | B6: =COUNTIFS(매핑!$A$2:$A$1498,"화면",매핑!$B$2:$B$1498,$A6) -> 14 | C6: =COUNTIFS(매핑!$A$2:$A$1498,"화면",매핑!$B$2:$B$1498,$A6,매핑!$E$2:$E$1498,"미실행") -> 13 | D6: =COUNTIFS(매핑!$A$2:$A$1498,"화면",매핑!$B$2:$B$1498,$A6,매핑!$E$2:$E$1498,"보류") -> 1
A7: 1-3 | B7: =COUNTIFS(매핑!$A$2:$A$1498,"화면",매핑!$B$2:$B$1498,$A7) -> 10 | C7: =COUNTIFS(매핑!$A$2:$A$1498,"화면",매핑!$B$2:$B$1498,$A7,매핑!$E$2:$E$1498,"미실행") -> 10 | D7: =COUNTIFS(매핑!$A$2:$A$1498,"화면",매핑!$B$2:$B$1498,$A7,매핑!$E$2:$E$1498,"보류") -> 0
A8: 1-5 | B8: =COUNTIFS(매핑!$A$2:$A$1498,"화면",매핑!$B$2:$B$1498,$A8) -> 16 | C8: =COUNTIFS(매핑!$A$2:$A$1498,"화면",매핑!$B$2:$B$1498,$A8,매핑!$E$2:$E$1498,"미실행") -> 15 | D8: =COUNTIFS(매핑!$A$2:$A$1498,"화면",매핑!$B$2:$B$1498,$A8,매핑!$E$2:$E$1498,"보류") -> 1
A9: 1-6 | B9: =COUNTIFS(매핑!$A$2:$A$1498,"화면",매핑!$B$2:$B$1498,$A9) -> 7 | C9: =COUNTIFS(매핑!$A$2:$A$1498,"화면",매핑!$B$2:$B$1498,$A9,매핑!$E$2:$E$1498,"미실행") -> 6 | D9: =COUNTIFS(매핑!$A$2:$A$1498,"화면",매핑!$B$2:$B$1498,$A9,매핑!$E$2:$E$1498,"보류") -> 1
A10: 2-5-1 | B10: =COUNTIFS(매핑!$A$2:$A$1498,"화면",매핑!$B$2:$B$1498,$A10) -> 7 | C10: =COUNTIFS(매핑!$A$2:$A$1498,"화면",매핑!$B$2:$B$1498,$A10,매핑!$E$2:$E$1498,"미실행") -> 6 | D10: =COUNTIFS(매핑!$A$2:$A$1498,"화면",매핑!$B$2:$B$1498,$A10,매핑!$E$2:$E$1498,"보류") -> 1
A11: 2-7 | B11: =COUNTIFS(매핑!$A$2:$A$1498,"화면",매핑!$B$2:$B$1498,$A11) -> 10 | C11: =COUNTIFS(매핑!$A$2:$A$1498,"화면",매핑!$B$2:$B$1498,$A11,매핑!$E$2:$E$1498,"미실행") -> 10 | D11: =COUNTIFS(매핑!$A$2:$A$1498,"화면",매핑!$B$2:$B$1498,$A11,매핑!$E$2:$E$1498,"보류") -> 0
A12: AUTH-01 | B12: =COUNTIFS(매핑!$A$2:$A$1498,"화면",매핑!$B$2:$B$1498,$A12) -> 13 | C12: =COUNTIFS(매핑!$A$2:$A$1498,"화면",매핑!$B$2:$B$1498,$A12,매핑!$E$2:$E$1498,"미실행") -> 13 | D12: =COUNTIFS(매핑!$A$2:$A$1498,"화면",매핑!$B$2:$B$1498,$A12,매핑!$E$2:$E$1498,"보류") -> 0
A13: AUTH-03 | B13: =COUNTIFS(매핑!$A$2:$A$1498,"화면",매핑!$B$2:$B$1498,$A13) -> 22 | C13: =COUNTIFS(매핑!$A$2:$A$1498,"화면",매핑!$B$2:$B$1498,$A13,매핑!$E$2:$E$1498,"미실행") -> 15 | D13: =COUNTIFS(매핑!$A$2:$A$1498,"화면",매핑!$B$2:$B$1498,$A13,매핑!$E$2:$E$1498,"보류") -> 7
... A42: SVC-08 | B42: =COUNTIFS(매핑!$A$2:$A$1498,"화면",매핑!$B$2:$B$1498,$A42) -> 12 | C42: =COUNTIFS(매핑!$A$2:$A$1498,"화면",매핑!$B$2:$B$1498,$A42,매핑!$E$2:$E$1498,"미실행") -> 11 | D42: =COUNTIFS(매핑!$A$2:$A$1498,"화면",매핑!$B$2:$B$1498,$A42,매핑!$E$2:$E$1498,"보류") -> 1

Sheet 요건별(RTM)
A1: 요건 ID | B1: 정의 절 | C1: TC 건수 | D1: TC ID
A2: AC-01 | B2: 2.3 수용 기준 (Acceptance Criteria) | C2: =COUNTIFS(매핑!$A$2:$A$1498,"요건",매핑!$B$2:$B$1498,$A2) -> 2 | D2: TC-INAV-01-15 · TC-AC-01-00
A3: AC-02 | B3: 2.3 수용 기준 (Acceptance Criteria) | C3: =COUNTIFS(매핑!$A$2:$A$1498,"요건",매핑!$B$2:$B$1498,$A3) -> 1 | D3: TC-AC-02-00
A4: AC-03 | B4: 2.3 수용 기준 (Acceptance Criteria) | C4: =COUNTIFS(매핑!$A$2:$A$1498,"요건",매핑!$B$2:$B$1498,$A4) -> 1 | D4: TC-ONAV-01-07
A5: AC-04 | B5: 2.3 수용 기준 (Acceptance Criteria) | C5: =COUNTIFS(매핑!$A$2:$A$1498,"요건",매핑!$B$2:$B$1498,$A5) -> 1 | D5: TC-INAV-01-28
A6: AC-05 | B6: 2.3 수용 기준 (Acceptance Criteria) | C6: =COUNTIFS(매핑!$A$2:$A$1498,"요건",매핑!$B$2:$B$1498,$A6) -> 98 | D6: TC-AUTH-01-04 · TC-AUTH-04-04 · TC-AUTH-04-06 · TC-AUTH-04-07 · TC-AUTH-04-16 · TC-AUTH-04-21 · TC-AUTH-03-07 · TC-AUTH-03-13 · TC-AUTH-03-15 · TC-AUTH-03-20 · TC-HOME-01-08 · TC-HOME-01-10 · TC-HOME-01-13 · TC-ROUTE-01-05 · TC-ROUTE-01-11 · TC-ROUTE-01-13 · TC-ROUTE-01-14 · TC-ROUTE-02-10 · TC-ROUTE-02-11 · TC-ROUTE-02-13 · TC-SEARCH-01-08 · TC-SEARCH-01-09 · TC-SEARCH-01-11 · TC-SEARCH-02-03 · TC-SEARCH-02-05 · TC-SEARCH-02-09 · TC-ROUTE-03-11 · TC-ONAV-01-06 · TC-ONAV-01-19 · TC-ONAV-01-20 · TC-ONAV-01-22 · TC-ONAV-01-23 · TC-INAV-01-20 · TC-INAV-01-22 · TC-INAV-01-23 · TC-INAV-01-26 · TC-1-3-02 · TC-1-3-07 · TC-1-3-08 · TC-BUS-03-02 · TC-BUS-03-08 · TC-2-5-1-02 · TC-2-5-1-04 · TC-BUS-01-03 · TC-BUS-01-10 · TC-BUS-01-12 · TC-SVC-08-04 · TC-SVC-08-09 · TC-SVC-08-11 · TC-1-2-08 · TC-SVC-05-12 · TC-SVC-06-01 · TC-SVC-06-02 · TC-SVC-06-03 · TC-SVC-06-04 · TC-SVC-06-06 · TC-1-5-07 · TC-1-5-08 · TC-1-5-09 · TC-1-5-14 · TC-1-5-15 · TC-1-6-06 · TC-1-6-07 · TC-REPORT-01-14 · TC-REPORT-01-17 · TC-REPORT-01-18 · TC-REPORT-02-03 · TC-REPORT-02-06 · TC-MY-01-05 · TC-MY-01-09 · TC-MY-01-11 · TC-MY-01-12 · TC-MY-01-14 · TC-AUTH-04-55 · TC-AUTH-04-56 · TC-AUTH-04-57 · TC-REPORT-03-02 · TC-REPORT-03-04 · TC-MY-11-03 · TC-MY-11-04 · TC-FAV-01-12 · TC-FAV-01-13 · TC-FAV-01-14 · TC-FAV-01-15 · TC-FAV-01-20 · TC-HOME-04-03 · TC-MY-06-01 · TC-MY-06-04 · TC-2-7-02 · TC-2-7-08 · TC-S2-2-01 · TC-S2-2-05 · TC-S2-2-14 · TC-S2-3-02 · TC-S2-3-06 · TC-S2-3-10 · TC-S2-4-06 · TC-S-3-00
A7: AC-06 | B7: 2.3 수용 기준 (Acceptance Criteria) | C7: =COUNTIFS(매핑!$A$2:$A$1498,"요건",매핑!$B$2:$B$1498,$A7) -> 19 | D7: TC-AUTH-04-10 · TC-AUTH-04-22 · TC-AUTH-03-19 · TC-HOME-01-12 · TC-ROUTE-01-16 · TC-SEARCH-01-13 · TC-ONAV-01-26 · TC-INAV-01-25 · TC-BUS-01-22 · TC-SVC-08-06 · TC-SVC-05-10 · TC-1-5-13 · TC-REPORT-01-19 · TC-REPORT-02-12 · TC-MY-01-04 · TC-MY-01-19 · TC-FAV-01-18 · TC-MY-06-03 · TC-L-3-00
A8: AC-07 | B8: 2.3 수용 기준 (Acceptance Criteria) | C8: =COUNTIFS(매핑!$A$2:$A$1498,"요건",매핑!$B$2:$B$1498,$A8) -> 1 | D8: TC-ROUTE-02-05
A9: AC-08 | B9: 2.3 수용 기준 (Acceptance Criteria) | C9: =COUNTIFS(매핑!$A$2:$A$1498,"요건",매핑!$B$2:$B$1498,$A9) -> 1 | D9: TC-AC-08-00
A10: AC-09 | B10: 2.3 수용 기준 (Acceptance Criteria) | C10: =COUNTIFS(매핑!$A$2:$A$1498,"요건",매핑!$B$2:$B$1498,$A10) -> 1 | D10: TC-INAV-01-29
A11: AC-10 | B11: 2.3 수용 기준 (Acceptance Criteria) | C11: =COUNTIFS(매핑!$A$2:$A$1498,"요건",매핑!$B$2:$B$1498,$A11) -> 1 | D11: TC-S2-2-18
A12: AC-11 | B12: 2.3 수용 기준 (Acceptance Criteria) | C12: =COUNTIFS(매핑!$A$2:$A$1498,"요건",매핑!$B$2:$B$1498,$A12) -> 1 | D12: TC-AC-11-00
A13: AC-12 | B13: 2.3 수용 기준 (Acceptance Criteria) | C13: =COUNTIFS(매핑!$A$2:$A$1498,"요건",매핑!$B$2:$B$1498,$A13) -> 1 | D13: TC-AC-12-00
... A86: NFR-15 | B86: 2.4 비기능 요구사항 ★ | C86: =COUNTIFS(매핑!$A$2:$A$1498,"요건",매핑!$B$2:$B$1498,$A86) -> 1 | D86: TC-AC-11-00
A87: NFR-16 | B87: 2.4 비기능 요구사항 ★ | C87: =COUNTIFS(매핑!$A$2:$A$1498,"요건",매핑!$B$2:$B$1498,$A87) -> 0
A88: S-1 | B88: 7.8 형태·간격 토큰 — radius · spacing | C88: =COUNTIFS(매핑!$A$2:$A$1498,"요건",매핑!$B$2:$B$1498,$A88) -> 10 | D88: TC-AUTH-04-20 · TC-AUTH-03-18 · TC-HOME-01-11 · TC-ROUTE-01-15 · TC-1-2-09 · TC-SVC-05-03 · TC-REPORT-01-19 · TC-MY-01-19 · TC-FAV-01-16 · TC-HOME-04-04
A89: S-2 | B89: 7.8 형태·간격 토큰 — radius · spacing | C89: =COUNTIFS(매핑!$A$2:$A$1498,"요건",매핑!$B$2:$B$1498,$A89) -> 10 | D89: TC-AUTH-04-20 · TC-AUTH-03-18 · TC-HOME-01-11 · TC-ROUTE-01-15 · TC-1-2-09 · TC-SVC-05-03 · TC-REPORT-02-12 · TC-MY-01-19 · TC-FAV-01-16 · TC-HOME-04-04
A90: S-3 | B90: 7.8 형태·간격 토큰 — radius · spacing | C90: =COUNTIFS(매핑!$A$2:$A$1498,"요건",매핑!$B$2:$B$1498,$A90) -> 1 | D90: TC-S-3-00
A91: S-4 | B91: 7.8 형태·간격 토큰 — radius · spacing | C91: =COUNTIFS(매핑!$A$2:$A$1498,"요건",매핑!$B$2:$B$1498,$A91) -> 3 | D91: TC-SVC-05-10 · TC-FAV-01-18 · TC-MY-06-03
A92: S-5 | B92: 7.8 형태·간격 토큰 — radius · spacing | C92: =COUNTIFS(매핑!$A$2:$A$1498,"요건",매핑!$B$2:$B$1498,$A92) -> 1 | D92: TC-S-5-00
A93: S-6 | B93: 7.8 형태·간격 토큰 — radius · spacing | C93: =COUNTIFS(매핑!$A$2:$A$1498,"요건",매핑!$B$2:$B$1498,$A93) -> 1 | D93: TC-S-5-00
A94: SC-01 | B94: 7.4 화면 정의 | C94: =COUNTIFS(매핑!$A$2:$A$1498,"요건",매핑!$B$2:$B$1498,$A94) -> 11 | D94: TC-HOME-01-01 · TC-HOME-01-02 · TC-HOME-01-03 · TC-HOME-01-04 · TC-HOME-01-05 · TC-HOME-01-06 · TC-HOME-01-07 · TC-HOME-01-09 · TC-HOME-01-15 · TC-HOME-01-16 · TC-HOME-01-17
A95: SC-02 | B95: 7.4 화면 정의 | C95: =COUNTIFS(매핑!$A$2:$A$1498,"요건",매핑!$B$2:$B$1498,$A95) -> 12 | D95: TC-ROUTE-01-01 · TC-ROUTE-01-02 · TC-ROUTE-01-03 · TC-ROUTE-01-11 · TC-ROUTE-01-12 · TC-ROUTE-02-01 · TC-ROUTE-02-03 · TC-ROUTE-02-05 · TC-ROUTE-02-07 · TC-ROUTE-02-08 · TC-ROUTE-02-09 · TC-ROUTE-02-12
A96: SC-03 | B96: 7.4 화면 정의 | C96: =COUNTIFS(매핑!$A$2:$A$1498,"요건",매핑!$B$2:$B$1498,$A96) -> 3 | D96: TC-SEARCH-02-01 · TC-SEARCH-02-02 · TC-SEARCH-02-04
A97: SC-04 | B97: 7.4 화면 정의 | C97: =COUNTIFS(매핑!$A$2:$A$1498,"요건",매핑!$B$2:$B$1498,$A97) -> 8 | D97: TC-ROUTE-03-06 · TC-ONAV-01-01 · TC-ONAV-01-02 · TC-ONAV-01-03 · TC-ONAV-01-04 · TC-ONAV-01-05 · TC-ONAV-01-06 · TC-ONAV-01-27
A98: SC-05 | B98: 7.4 화면 정의 | C98: =COUNTIFS(매핑!$A$2:$A$1498,"요건",매핑!$B$2:$B$1498,$A98) -> 10 | D98: TC-INAV-01-01 · TC-INAV-01-03 · TC-INAV-01-04 · TC-INAV-01-05 · TC-INAV-01-06 · TC-INAV-01-08 · TC-INAV-01-12 · TC-INAV-01-14 · TC-INAV-01-20 · TC-SVC-08-12
A99: SC-06 | B99: 7.4 화면 정의 | C99: =COUNTIFS(매핑!$A$2:$A$1498,"요건",매핑!$B$2:$B$1498,$A99) -> 1 | D99: TC-S2-3-16
... A137: V-9 | B137: 7.4 화면 정의 | C137: =COUNTIFS(매핑!$A$2:$A$1498,"요건",매핑!$B$2:$B$1498,$A137) -> 9 | D137: TC-INAV-01-21 · TC-BUS-03-10 · TC-1-5-08 · TC-REPORT-01-10 · TC-REPORT-01-18 · TC-2-7-04 · TC-2-7-05 · TC-S2-2-12 · TC-S2-3-10
